Workbook
Name MODO_DEMO: '01_CONTROL_PANEL'!$C$7
Name KG_SACO_STD: '01_CONTROL_PANEL'!$C$9
Name SACO_PALETE_STD: '01_CONTROL_PANEL'!$C$10
Name KG_SACO_EXT: '01_CONTROL_PANEL'!$C$11
Name SACO_PALETE_EXT: '01_CONTROL_PANEL'!$C$12
Name KG_PALETE: '01_CONTROL_PANEL'!$C$13
Name CONCHA_M3: '01_CONTROL_PANEL'!$C$14
Name ICMS_NOMINAL: '01_CONTROL_PANEL'!$C$16
Name ICMS_REDUCAO: '01_CONTROL_PANEL'!$C$17
Name ICMS_PCT_DEVIDO: '01_CONTROL_PANEL'!$C$18
Name ICMS_EFETIVO: '01_CONTROL_PANEL'!$C$19
Name PIS_DEBITO: '01_CONTROL_PANEL'!$C$21
Name COFINS_DEBITO: '01_CONTROL_PANEL'!$C$22
Name IRPJ_ALIQ: '01_CONTROL_PANEL'!$C$24
Name IRPJ_ADIC: '01_CONTROL_PANEL'!$C$25
Name CSLL_ALIQ: '01_CONTROL_PANEL'!$C$26
Name SUDENE_REDUCAO: '01_CONTROL_PANEL'!$C$27
Name CUSTO_CAPITAL_ANO: '01_CONTROL_PANEL'!$C$29
Name INADIMPL_PCT: '01_CONTROL_PANEL'!$C$30
Name DIAS_ANO: '01_CONTROL_PANEL'!$C$31
Name MAT_CLASSE_A: '01_CONTROL_PANEL'!$C$33
Name MAT_CLASSE_B: '01_CONTROL_PANEL'!$C$34
Name VOLUME_ANO_T: '01_CONTROL_PANEL'!$C$35

Sheet 00_README
A1: SKAL INDUSTRIAL COST INTELLIGENCE SYSTEM
A2: Digital Cost Twin da operacao industrial — Grupo Kalfix / SKAL. Gerado por build_skal_cost_system.py (fonte da verdade da estrutura).
B4: O QUE E | C4: Sistema modular e auditavel que responde, para qualquer SKU: quanto custou, quanto deveria ter custado, quanto custaria hoje, qual o desvio, onde/porque ocorreu, quanto e controlavel, e quanto vale elimina-lo.
B5: CINCO FUNCOES | C5: 1) Cost Accounting (quanto custou) 2) Cost Engineering (quanto deveria) 3) Cost Control (onde desviou) 4) Cost Reduction (quanto economizar) 5) Profitability Intelligence (onde ganha/perde dinheiro).
B6: COMO USAR | C6: Preencha as celulas AMARELAS (INPUT). Celulas brancas sao FORMULA; azuis sao dados de outra aba (LINKED); verdes sao CONTROL; vermelhas sao ALERT. Nao altere formulas estruturais. Premissas globais ficam em 01_CONTROL_PANEL.
B7: MODO DEMO | C7: 01_CONTROL_PANEL!MODO_DEMO liga um pequeno dataset de DEMONSTRACAO (marcado em cada linha) que permite os testes matematicos. Numeros DEMO NAO sao dados reais da SKAL — veja DATA_GAPS para o que precisa ser preenchido.
B8: RECONCILIACAO | C8: Regra central: Standard Cost + Variances (PPV+Uso+Mix+Yield) = Actual Cost, residual -> 0. BOM fecha fisicamente. Nenhum custo e rateado sem driver causal (vai para UNALLOCATED).
B10: DICIONARIO DE INDICADORES-CHAVE
B11: Indicador | C11: Definicao / Formula | D11: Unidade | E11: Resp.
B12: Landed Net Cost | C12: Bruto - descontos - creditos recup. + frete/seguro/descarga + trib. nao recup. | D12: R$/t | E12: Compras/Fiscal
B13: Material Cost / Good Ton | C13: Custo total materiais consumidos / toneladas boas liberadas | D13: R$/t | E13: Producao/Contr.
B14: PPV | C14: (Preco real - preco padrao) x quantidade real | D14: R$ | E14: Compras
B15: Usage Variance | C15: (Qtd real - qtd padrao permitida) x preco padrao | D15: R$ | E15: Producao
B16: Mix Variance | C16: Efeito da alteracao da composicao relativa da formula (sub-split do uso) | D16: R$ | E16: Tecnico
B17: Yield Variance | C17: (Output bom esperado - obtido) valorizado ao custo padrao | D17: R$ | E17: Producao
B18: Unused Capacity Cost | C18: Horas ociosas x custo/hora de capacidade pratica (NAO rateado ao produto) | D18: R$ | E18: Controladoria
B19: COPQ | C19: Custo da ma qualidade: scrap+reprocesso+retrabalho+devolucao+frete reverso... | D19: R$ | E19: Qualidade
B20: Cost Gap | C20: Actual -> Current Std -> Best Demonstrated -> Entitlement -> Teorico | D20: R$/t | E20: Controladoria
B21: Pocket Price | C21: Preco tabela - descontos - bonif - rebate - comissao - frete - custo prazo - inadimpl. | D21: R$ | E21: Comercial
B22: Pocket Margin | C22: Pocket Price - custo reposicao - cost to serve - tributacao economica | D22: R$ | E22: Comercial/Contr.
... B24: Saving Realizado | C24: Saving com evidencia operacional + confirmacao financeira + reconciliacao | D24: R$ | E24: Controladoria
B26: INDICE DE ABAS
B27: Aba | C27: Grupo | D27: Proposito
B28: 00_README | C28: Doc | D28: Documentacao, metodologia e indice
B29: 01_CONTROL_PANEL | C29: Core | D29: Premissas globais parametrizadas
B30: 02_CALENDAR | C30: Core | D30: Periodos e vigencias
B31: 03_PRODUCTS | C31: Master Data | D31: Cadastro de produtos (SKU)
B32: 04_MATERIALS | C32: Master Data | D32: Cadastro de materias-primas
B33: 05_SUPPLIERS | C33: Master Data | D33: Cadastro de fornecedores
B34: 06_BOM | C34: Engineering | D34: Formulacao tecnica e economica (BOM)
B35: 07_BOM_VERSION | C35: Engineering | D35: Controle de versoes de formulacao
B36: 09_LANDED_COST | C36: Procurement | D36: Custo liquido posto fabrica
B37: 10_TAX_RULES | C37: Tax | D37: Motor tributario (regras por vigencia)
B38: 11_TAX_CREDITS | C38: Tax | D38: Creditos tributarios (potencial->monetizado)
... B86: R5_FRETES_CTE | C86: Real | D86: Fretes inbound (CT-e)

Sheet 01_CONTROL_PANEL
A1: PAINEL DE CONTROLE — PREMISSAS GLOBAIS
A2: Toda premissa critica vive aqui e e referenciada por NOME. Nenhuma aliquota digitada dentro de formula. Edite apenas a coluna VALOR (amarela).
A4: Legenda: | B4: INPUT (editavel) | D4: FORMULA | F4: LINKED (de outra aba) | H4: CONTROL | J4: ALERT | L4: CHAVE/ID
A6: # | B6: Parametro | C6: Valor | D6: Un. | E6: Descricao / regra | F6: Fonte | G6: Responsavel
A7: MODO_DEMO | B7: Modo demonstracao (TRUE/FALSE) | C7: TRUE | D7: - | E7: TRUE liga dataset DEMO p/ testes; FALSE zera exemplos | F7: Controladoria | G7: Controller
B8: — CONVERSOES DE EMBALAGEM —
A9: KG_SACO_STD | B9: kg por saco (padrao) | C9: 15 | D9: kg | E9: Linhas gerais SKAL | F9: Producao | G9: Sup. Prod.
A10: SACO_PALETE_STD | B10: sacos por palete (padrao) | C10: 100 | D10: un | E10: Linhas gerais | F10: Producao | G10: Sup. Prod.
A11: KG_SACO_EXT | B11: kg por saco (linha Extras) | C11: 20 | D11: kg | E11: Multiuso/Graute/Reboco/Contrapiso | F11: Producao | G11: Sup. Prod.
A12: SACO_PALETE_EXT | B12: sacos por palete (Extras) | C12: 75 | D12: un | E12: Linha Extras | F12: Producao | G12: Sup. Prod.
A13: KG_PALETE | B13: kg por palete (todas) | C13: 1500 | D13: kg | E13: 1.500 kg/palete em ambas as linhas | F13: Producao | G13: Sup. Prod.
A14: CONCHA_M3 | B14: m3 por concha (Komatsu WA200-5) | C14: 2.1 | D14: m3 | E14: Elo com Painel do Forno (areia) | F14: Producao | G14: Sup. Prod.
B15: — ICMS (beneficio 80%) —
A16: ICMS_NOMINAL | B16: ICMS aliquota nominal | C16: 0.225 | D16: % | E16: Aliquota cheia | F16: Fiscal | G16: Cont. Fiscal
A17: ICMS_REDUCAO | B17: ICMS reducao do beneficio | C17: 0.8 | D17: % | E17: Reducao de 80% do ICMS devido | F17: Fiscal | G17: Cont. Fiscal
A18: ICMS_PCT_DEVIDO | B18: ICMS % efetivamente devido | C18: =1-ICMS_REDUCAO | D18: % | E18: 1 menos reducao (da 20%) | F18: Fiscal | G18: Cont. Fiscal
A19: ICMS_EFETIVO | B19: ICMS efetivo (calc.) | C19: =ICMS_NOMINAL*ICMS_PCT_DEVIDO | D19: % | E19: nominal x %devido (=4,5%) NUNCA hardcoded | F19: Fiscal | G19: Cont. Fiscal
B20: — PIS/COFINS (Lucro Real, nao cumulativo) —
A21: PIS_DEBITO | B21: PIS debito | C21: 0.0165 | D21: % | E21: Nao cumulativo | F21: Fiscal | G21: Cont. Fiscal
A22: COFINS_DEBITO | B22: COFINS debito | C22: 0.076 | D22: % | E22: Nao cumulativo (soma 9,25%) | F22: Fiscal | G22: Cont. Fiscal
B23: — IRPJ / CSLL / SUDENE —
A24: IRPJ_ALIQ | B24: IRPJ aliquota | C24: 0.15 | D24: % | E24: 15% + adicional | F24: Fiscal | G24: Cont. Fiscal
A25: IRPJ_ADIC | B25: IRPJ adicional (>20k/mes) | C25: 0.1 | D25: % | E25: 10% sobre excedente | F25: Fiscal | G25: Cont. Fiscal
A26: CSLL_ALIQ | B26: CSLL aliquota | C26: 0.09 | D26: % | E26: NUNCA aplicar reducao SUDENE a CSLL | F26: Fiscal | G26: Cont. Fiscal
A27: SUDENE_REDUCAO | B27: SUDENE reducao IRPJ elegivel | C27: 0.75 | D27: % | E27: 75% do IRPJ elegivel (parametrizavel) | F27: Fiscal | G27: Diretoria
B28: — FINANCEIRO —
A29: CUSTO_CAPITAL_ANO | B29: Custo de capital anual | C29: 0.18 | D29: % | E29: Para custo de prazo e estoque (DEMO) | F29: Financeiro | G29: CFO
A30: INADIMPL_PCT | B30: Inadimplencia esperada (%) | C30: 0.015 | D30: % | E30: Taxa historica parametrizada (DEMO) | F30: Financeiro | G30: Credito
A31: DIAS_ANO | B31: Dias no ano (base financeira) | C31: 365 | D31: d | E31: Base p/ custo de prazo | F31: Financeiro | G31: CFO
B32: — MATERIALIDADE / GOVERNANCA —
A33: MAT_CLASSE_A | B33: Materialidade Classe A (R$/ano) | C33: 100000 | D33: R$ | E33: Impacto alto | F33: Controladoria | G33: Controller
A34: MAT_CLASSE_B | B34: Materialidade Classe B (R$/ano) | C34: 25000 | D34: R$ | E34: Impacto medio | F34: Controladoria | G34: Controller
A35: VOLUME_ANO_T | B35: Volume anual referencia (t) | C35: 70000 | D35: t | E35: Para anualizar gaps (DEMO) | F35: Comercial | G35: Diretoria

Sheet 02_CALENDAR
A1: CALENDAR
A2: Controle temporal. A reforma tributaria e tratada por DATA DE VIGENCIA (ver 10_TAX_RULES), nunca sobrescrevendo regra antiga.
A4: Legenda: | B4: INPUT (editavel) | D4: FORMULA | F4: LINKED (de outra aba) | H4: CONTROL | J4: ALERT | L4: CHAVE/ID
A6: PERIOD_ID | B6: Ano | C6: Mes | D6: Data ini | E6: Data fim | F6: Dias uteis | G6: Regime tributario vigente | H6: Status
A7: 2026-01 | B7: 2026 | C7: 1 | D7: 2026-01-01 | E7: 2026-01-31 | F7: 22 | G7: ICMS benef. 80% + PIS/COFINS n-cum | H7: Fechado
A8: 2026-02 | B8: 2026 | C8: 2 | D8: 2026-02-01 | E8: 2026-02-28 | F8: 20 | G8: ICMS benef. 80% + PIS/COFINS n-cum | H8: Fechado
A9: 2026-03 | B9: 2026 | C9: 3 | D9: 2026-03-01 | E9: 2026-03-31 | F9: 21 | G9: ICMS benef. 80% + PIS/COFINS n-cum | H9: Aberto
A11: ^ Linhas acima = dados DEMO (marcados). Abaixo: campos de entrada em branco para dados reais.

Sheet 03_PRODUCTS
A1: PRODUCTS
A2: Conversoes de embalagem automaticas. Excecao linha Extras (Multiuso/Graute/Reboco/Contrapiso): 20 kg/saco, 75 sacos/palete.
A4: Legenda: | B4: INPUT (editavel) | D4: FORMULA | F4: LINKED (de outra aba) | H4: CONTROL | J4: ALERT | L4: CHAVE/ID
A6: PRODUCT_ID | B6: Descricao | C6: Familia | D6: Linha | E6: Unid. comercial | F6: Extras? | G6: kg/saco | H6: sacos/ palete | I6: kg/palete | J6: FORMULA_ID | K6: Versao | L6: ROUTING_ID | M6: RESOURCE principal | N6: Familia setup | O6: NCM | P6: Unid. industrial | Q6: Status | R6: Vigencia ini | S6: Vigencia fim
A7: P001 | B7: Multiuso | C7: Extras | D7: Extras | E7: saco | F7: TRUE | G7: =IF(F7,KG_SACO_EXT,KG_SACO_STD) | H7: =IF(F7,SACO_PALETE_EXT,SACO_PALETE_STD) | I7: =G7*H7 | J7: F-P001 | K7: v1 | L7: RT-EXT | M7: RES-MIST1 | N7: Extras | O7: 3824.50.00 | P7: t | Q7: Ativo | R7: 2026-01-01
A8: P002 | B8: Argamassa Assentamento AC-III | C8: Assentamento | D8: Colante | E8: saco | F8: FALSE | G8: =IF(F8,KG_SACO_EXT,KG_SACO_STD) | H8: =IF(F8,SACO_PALETE_EXT,SACO_PALETE_STD) | I8: =G8*H8 | J8: F-P002 | K8: v1 | L8: RT-ARG | M8: RES-MIST1 | N8: Colante | O8: 3824.50.00 | P8: t | Q8: Ativo | R8: 2026-01-01
A9: P003 | B9: Rejunte | C9: Rejunte | D9: Rejunte | E9: saco | F9: FALSE | G9: =IF(F9,KG_SACO_EXT,KG_SACO_STD) | H9: =IF(F9,SACO_PALETE_EXT,SACO_PALETE_STD) | I9: =G9*H9 | J9: F-P003 | K9: v1 | L9: RT-REJ | M9: RES-MIST2 | N9: Rejunte | O9: 3824.50.00 | P9: t | Q9: Ativo | R9: 2026-01-01
G10: =IF($F10=TRUE,KG_SACO_EXT,KG_SACO_STD) | H10: =IF($F10=TRUE,SACO_PALETE_EXT,SACO_PALETE_STD) | I10: =G10*H10
G11: =IF($F11=TRUE,KG_SACO_EXT,KG_SACO_STD) | H11: =IF($F11=TRUE,SACO_PALETE_EXT,SACO_PALETE_STD) | I11: =G11*H11
G12: =IF($F12=TRUE,KG_SACO_EXT,KG_SACO_STD) | H12: =IF($F12=TRUE,SACO_PALETE_EXT,SACO_PALETE_STD) | I12: =G12*H12
G13: =IF($F13=TRUE,KG_SACO_EXT,KG_SACO_STD) | H13: =IF($F13=TRUE,SACO_PALETE_EXT,SACO_PALETE_STD) | I13: =G13*H13
G14: =IF($F14=TRUE,KG_SACO_EXT,KG_SACO_STD) | H14: =IF($F14=TRUE,SACO_PALETE_EXT,SACO_PALETE_STD) | I14: =G14*H14
G15: =IF($F15=TRUE,KG_SACO_EXT,KG_SACO_STD) | H15: =IF($F15=TRUE,SACO_PALETE_EXT,SACO_PALETE_STD) | I15: =G15*H15
G16: =IF($F16=TRUE,KG_SACO_EXT,KG_SACO_STD) | H16: =IF($F16=TRUE,SACO_PALETE_EXT,SACO_PALETE_STD) | I16: =G16*H16
G17: =IF($F17=TRUE,KG_SACO_EXT,KG_SACO_STD) | H17: =IF($F17=TRUE,SACO_PALETE_EXT,SACO_PALETE_STD) | I17: =G17*H17
G18: =IF($F18=TRUE,KG_SACO_EXT,KG_SACO_STD) | H18: =IF($F18=TRUE,SACO_PALETE_EXT,SACO_PALETE_STD) | I18: =G18*H18
G19: =IF($F19=TRUE,KG_SACO_EXT,KG_SACO_STD) | H19: =IF($F19=TRUE,SACO_PALETE_EXT,SACO_PALETE_STD) | I19: =G19*H19
G20: =IF($F20=TRUE,KG_SACO_EXT,KG_SACO_STD) | H20: =IF($F20=TRUE,SACO_PALETE_EXT,SACO_PALETE_STD) | I20: =G20*H20
G21: =IF($F21=TRUE,KG_SACO_EXT,KG_SACO_STD) | H21: =IF($F21=TRUE,SACO_PALETE_EXT,SACO_PALETE_STD) | I21: =G21*H21
... G46: =IF($F46=TRUE,KG_SACO_EXT,KG_SACO_STD) | H46: =IF($F46=TRUE,SACO_PALETE_EXT,SACO_PALETE_STD) | I46: =G46*H46

Sheet 04_MATERIALS
A1: MATERIALS
A2: Cada MP tem chave unica, funcao tecnica e substituto. Recuperabilidade tributaria alimenta o Landed Net Cost.
A4: Legenda: | B4: INPUT (editavel) | D4: FORMULA | F4: LINKED (de outra aba) | H4: CONTROL | J4: ALERT | L4: CHAVE/ID
A6: MATERIAL_ID | B6: Descricao | C6: Grupo | D6: Unid. | E6: NCM | F6: Funcao tecnica | G6: Substituto (MATERIAL_ID) | H6: Recuperavel ICMS? | I6: Recuperavel PIS/COFINS? | J6: Classe (A/B/C) | K6: Fonte | L6: Responsavel | M6: Vigencia ini | N6: Vigencia fim | O6: Atualizado em | P6: Comentario
A7: M001 | B7: Cimento CP-II-32 | C7: Aglomerante | D7: t | E7: 2523.29.10 | F7: Aglomerante estrutural | H7: Sim | I7: Sim | J7: A
A8: M002 | B8: Areia industrial seca | C8: Agregado | D8: t | E8: 2505.10.00 | F8: Agregado/carga | H8: Sim | I8: Sim | J8: A
A9: M003 | B9: Cal hidratada CH-I | C9: Aglomerante | D9: t | E9: 2522.20.00 | F9: Plastificante/retencao | H9: Sim | I9: Sim | J9: B
A10: M004 | B10: Aditivo retentor de agua (HEC) | C10: Aditivo | D10: kg | E10: 3912.39.00 | F10: Retencao de agua/trabalhab. | H10: Sim | I10: Sim | J10: B
A11: M005 | B11: Pigmento oxido de ferro | C11: Aditivo | D11: kg | E11: 2821.10.00 | F11: Coloracao | H11: Sim | I11: Sim | J11: C
A13: ^ Linhas acima = dados DEMO (marcados). Abaixo: campos de entrada em branco para dados reais.

Sheet 05_SUPPLIERS
A1: SUPPLIERS
A2: Base para Landed Cost, Supplier TCO e Should Cost.
A4: Legenda: | B4: INPUT (editavel) | D4: FORMULA | F4: LINKED (de outra aba) | H4: CONTROL | J4: ALERT | L4: CHAVE/ID
A6: SUPPLIER_ID | B6: Razao social | C6: UF | D6: Fornece (grupo) | E6: Lead time (d) | F6: Lote min (t) | G6: Condicao pgto (d) | H6: Rating qualidade | I6: Estrategico? | J6: Fonte | K6: Responsavel | L6: Vigencia ini | M6: Vigencia fim | N6: Atualizado em | O6: Comentario
A7: S001 | B7: Cimento Fornecedor A | C7: CE | D7: Cimento | E7: 3 | F7: 27 | G7: 28 | H7: A | I7: Sim
A8: S002 | B8: Mineracao Areia (ASSIS/SKAL) | C8: CE | D8: Areia | E8: 2 | F8: 30 | G8: 21 | H8: B | I8: Sim
A9: S003 | B9: Quimica Aditivos B | C9: SP | D9: Aditivo/Pigmento | E9: 10 | F9: 1 | G9: 30 | H9: A | I9: Nao
A11: ^ Linhas acima = dados DEMO (marcados). Abaixo: campos de entrada em branco para dados reais.

Sheet 06_BOM
A1: BOM
A2: kg/t x LANDED NET R$/t = custo padrao de material. Soma de kg/t deve fechar com o peso tecnico (1.000 kg/t). Alerta se nao fechar.
A4: Legenda: | B4: INPUT (editavel) | D4: FORMULA | F4: LINKED (de outra aba) | H4: CONTROL | J4: ALERT | L4: CHAVE/ID
A6: PRODUCT_ID | B6: FORMULA_ID | C6: Versao | D6: MATERIAL_ID | E6: kg / t produto | F6: % massa | G6: Min kg/t | H6: Max kg/t | I6: Funcao tecnica | J6: Substituto | K6: LANDED R$/t (link) | L6: Custo padrao R$/t produto | M6: KEY (prod|mat)
A7: P001 | B7: F-P001 | C7: v1 | D7: M001 | E7: 250 | F7: =E7/1000 | I7: Aglomerante | K7: =IFERROR(INDEX('09_LANDED_COST'!$P$7:$P$47,MATCH(D7,'09_LANDED_COST'!$A$7:$A$47,0)),0) | L7: =E7/1000*K7 | M7: =A7&"|"&D7
A8: P001 | B8: F-P001 | C8: v1 | D8: M002 | E8: 700 | F8: =E8/1000 | I8: Agregado | K8: =IFERROR(INDEX('09_LANDED_COST'!$P$7:$P$47,MATCH(D8,'09_LANDED_COST'!$A$7:$A$47,0)),0) | L8: =E8/1000*K8 | M8: =A8&"|"&D8
A9: P001 | B9: F-P001 | C9: v1 | D9: M003 | E9: 45 | F9: =E9/1000 | I9: Plastificante | K9: =IFERROR(INDEX('09_LANDED_COST'!$P$7:$P$47,MATCH(D9,'09_LANDED_COST'!$A$7:$A$47,0)),0) | L9: =E9/1000*K9 | M9: =A9&"|"&D9
A10: P001 | B10: F-P001 | C10: v1 | D10: M004 | E10: 5 | F10: =E10/1000 | I10: Retentor agua | K10: =IFERROR(INDEX('09_LANDED_COST'!$P$7:$P$47,MATCH(D10,'09_LANDED_COST'!$A$7:$A$47,0)),0) | L10: =E10/1000*K10 | M10: =A10&"|"&D10
A11: P002 | B11: F-P002 | C11: v1 | D11: M001 | E11: 300 | F11: =E11/1000 | I11: Aglomerante | K11: =IFERROR(INDEX('09_LANDED_COST'!$P$7:$P$47,MATCH(D11,'09_LANDED_COST'!$A$7:$A$47,0)),0) | L11: =E11/1000*K11 | M11: =A11&"|"&D11
A12: P002 | B12: F-P002 | C12: v1 | D12: M002 | E12: 650 | F12: =E12/1000 | I12: Agregado | K12: =IFERROR(INDEX('09_LANDED_COST'!$P$7:$P$47,MATCH(D12,'09_LANDED_COST'!$A$7:$A$47,0)),0) | L12: =E12/1000*K12 | M12: =A12&"|"&D12
A13: P002 | B13: F-P002 | C13: v1 | D13: M003 | E13: 45 | F13: =E13/1000 | I13: Plastificante | K13: =IFERROR(INDEX('09_LANDED_COST'!$P$7:$P$47,MATCH(D13,'09_LANDED_COST'!$A$7:$A$47,0)),0) | L13: =E13/1000*K13 | M13: =A13&"|"&D13
A14: P002 | B14: F-P002 | C14: v1 | D14: M004 | E14: 5 | F14: =E14/1000 | I14: Retentor agua | K14: =IFERROR(INDEX('09_LANDED_COST'!$P$7:$P$47,MATCH(D14,'09_LANDED_COST'!$A$7:$A$47,0)),0) | L14: =E14/1000*K14 | M14: =A14&"|"&D14
A15: P003 | B15: F-P003 | C15: v1 | D15: M001 | E15: 350 | F15: =E15/1000 | I15: Aglomerante | K15: =IFERROR(INDEX('09_LANDED_COST'!$P$7:$P$47,MATCH(D15,'09_LANDED_COST'!$A$7:$A$47,0)),0) | L15: =E15/1000*K15 | M15: =A15&"|"&D15
A16: P003 | B16: F-P003 | C16: v1 | D16: M002 | E16: 600 | F16: =E16/1000 | I16: Agregado | K16: =IFERROR(INDEX('09_LANDED_COST'!$P$7:$P$47,MATCH(D16,'09_LANDED_COST'!$A$7:$A$47,0)),0) | L16: =E16/1000*K16 | M16: =A16&"|"&D16
A17: P003 | B17: F-P003 | C17: v1 | D17: M004 | E17: 8 | F17: =E17/1000 | I17: Retentor agua | K17: =IFERROR(INDEX('09_LANDED_COST'!$P$7:$P$47,MATCH(D17,'09_LANDED_COST'!$A$7:$A$47,0)),0) | L17: =E17/1000*K17 | M17: =A17&"|"&D17
A18: P003 | B18: F-P003 | C18: v1 | D18: M005 | E18: 42 | F18: =E18/1000 | I18: Pigmento | K18: =IFERROR(INDEX('09_LANDED_COST'!$P$7:$P$47,MATCH(D18,'09_LANDED_COST'!$A$7:$A$47,0)),0) | L18: =E18/1000*K18 | M18: =A18&"|"&D18
F19: =IF(E19="","",E19/1000) | K19: =IF(D19="","",IFERROR(INDEX('09_LANDED_COST'!$P$7:$P$47,MATCH(D19,'09_LANDED_COST'!$A$7:$A$47,0)),0)) | L19: =IF(E19="","",E19/1000*K19) | M19: =IF(A19="","",A19&"|"&D19)
F20: =IF(E20="","",E20/1000) | K20: =IF(D20="","",IFERROR(INDEX('09_LANDED_COST'!$P$7:$P$47,MATCH(D20,'09_LANDED_COST'!$A$7:$A$47,0)),0)) | L20: =IF(E20="","",E20/1000*K20) | M20: =IF(A20="","",A20&"|"&D20)
F21: =IF(E21="","",E21/1000) | K21: =IF(D21="","",IFERROR(INDEX('09_LANDED_COST'!$P$7:$P$47,MATCH(D21,'09_LANDED_COST'!$A$7:$A$47,0)),0)) | L21: =IF(E21="","",E21/1000*K21) | M21: =IF(A21="","",A21&"|"&D21)
F22: =IF(E22="","",E22/1000) | K22: =IF(D22="","",IFERROR(INDEX('09_LANDED_COST'!$P$7:$P$47,MATCH(D22,'09_LANDED_COST'!$A$7:$A$47,0)),0)) | L22: =IF(E22="","",E22/1000*K22) | M22: =IF(A22="","",A22&"|"&D22)
F23: =IF(E23="","",E23/1000) | K23: =IF(D23="","",IFERROR(INDEX('09_LANDED_COST'!$P$7:$P$47,MATCH(D23,'09_LANDED_COST'!$A$7:$A$47,0)),0)) | L23: =IF(E23="","",E23/1000*K23) | M23: =IF(A23="","",A23&"|"&D23)
F24: =IF(E24="","",E24/1000) | K24: =IF(D24="","",IFERROR(INDEX('09_LANDED_COST'!$P$7:$P$47,MATCH(D24,'09_LANDED_COST'!$A$7:$A$47,0)),0)) | L24: =IF(E24="","",E24/1000*K24) | M24: =IF(A24="","",A24&"|"&D24)
F25: =IF(E25="","",E25/1000) | K25: =IF(D25="","",IFERROR(INDEX('09_LANDED_COST'!$P$7:$P$47,MATCH(D25,'09_LANDED_COST'!$A$7:$A$47,0)),0)) | L25: =IF(E25="","",E25/1000*K25) | M25: =IF(A25="","",A25&"|"&D25)
F26: =IF(E26="","",E26/1000) | K26: =IF(D26="","",IFERROR(INDEX('09_LANDED_COST'!$P$7:$P$47,MATCH(D26,'09_LANDED_COST'!$A$7:$A$47,0)),0)) | L26: =IF(E26="","",E26/1000*K26) | M26: =IF(A26="","",A26&"|"&D26)
F27: =IF(E27="","",E27/1000) | K27: =IF(D27="","",IFERROR(INDEX('09_LANDED_COST'!$P$7:$P$47,MATCH(D27,'09_LANDED_COST'!$A$7:$A$47,0)),0)) | L27: =IF(E27="","",E27/1000*K27) | M27: =IF(A27="","",A27&"|"&D27)
F28: =IF(E28="","",E28/1000) | K28: =IF(D28="","",IFERROR(INDEX('09_LANDED_COST'!$P$7:$P$47,MATCH(D28,'09_LANDED_COST'!$A$7:$A$47,0)),0)) | L28: =IF(E28="","",E28/1000*K28) | M28: =IF(A28="","",A28&"|"&D28)
F29: =IF(E29="","",E29/1000) | K29: =IF(D29="","",IFERROR(INDEX('09_LANDED_COST'!$P$7:$P$47,MATCH(D29,'09_LANDED_COST'!$A$7:$A$47,0)),0)) | L29: =IF(E29="","",E29/1000*K29) | M29: =IF(A29="","",A29&"|"&D29)
F30: =IF(E30="","",E30/1000) | K30: =IF(D30="","",IFERROR(INDEX('09_LANDED_COST'!$P$7:$P$47,MATCH(D30,'09_LANDED_COST'!$A$7:$A$47,0)),0)) | L30: =IF(E30="","",E30/1000*K30) | M30: =IF(A30="","",A30&"|"&D30)
... F66: =IF(E66="","",E66/1000) | K66: =IF(D66="","",IFERROR(INDEX('09_LANDED_COST'!$P$7:$P$47,MATCH(D66,'09_LANDED_COST'!$A$7:$A$47,0)),0)) | L66: =IF(E66="","",E66/1000*K66) | M66: =IF(A66="","",A66&"|"&D66)
A69: CONTROLE — FECHAMENTO DA FORMULACAO (peso tecnico)
A70: PRODUCT_ID | B70: Soma kg/t | C70: Peso alvo | D70: Fecha? | E70: Custo padrao MATERIAL R$/t
A71: P001 | B71: =SUMIF($A$7:$A$67,A71,$E$7:$E$67) | C71: =KG_PALETE/ (KG_PALETE/1000) | D71: =IF(ABS(B71-1000)<=1,"OK","VERIFICAR") | E71: =SUMIF($A$7:$A$67,A71,$L$7:$L$67)
A72: P002 | B72: =SUMIF($A$7:$A$67,A72,$E$7:$E$67) | C72: =KG_PALETE/ (KG_PALETE/1000) | D72: =IF(ABS(B72-1000)<=1,"OK","VERIFICAR") | E72: =SUMIF($A$7:$A$67,A72,$L$7:$L$67)
A73: P003 | B73: =SUMIF($A$7:$A$67,A73,$E$7:$E$67) | C73: =KG_PALETE/ (KG_PALETE/1000) | D73: =IF(ABS(B73-1000)<=1,"OK","VERIFICAR") | E73: =SUMIF($A$7:$A$67,A73,$L$7:$L$67)

Sheet 07_BOM_VERSION
A1: BOM VERSION
A2: Historico versionado de formulas. Nunca sobrescrever; criar nova versao com vigencia.
A4: Legenda: | B4: INPUT (editavel) | D4: FORMULA | F4: LINKED (de outra aba) | H4: CONTROL | J4: ALERT | L4: CHAVE/ID
A6: FORMULA_ID | B6: PRODUCT_ID | C6: Versao | D6: Motivo alteracao | E6: Vigencia ini | F6: Vigencia fim | G6: Aprovador | H6: Status
A7: F-P001 | B7: P001 | C7: v1 | D7: Versao base 2026 | E7: 2026-01-01 | G7: Eng. Tecnico | H7: Vigente
A8: F-P002 | B8: P002 | C8: v1 | D8: Versao base 2026 | E8: 2026-01-01 | G8: Eng. Tecnico | H8: Vigente
A9: F-P003 | B9: P003 | C9: v1 | D9: Versao base 2026 | E9: 2026-01-01 | G9: Eng. Tecnico | H9: Vigente
A11: ^ Linhas acima = dados DEMO (marcados). Abaixo: campos de entrada em branco para dados reais.

Sheet 09_LANDED_COST
A1: LANDED COST
A2: LANDED NET = bruto - desconto - rebate + frete + seguro + descarga + armazenagem + trib.nao-recup - creditos recuperaveis. Nunca usar preco de NF puro.
A4: Legenda: | B4: INPUT (editavel) | D4: FORMULA | F4: LINKED (de outra aba) | H4: CONTROL | J4: ALERT | L4: CHAVE/ID
A6: MATERIAL_ID | B6: SUPPLIER_ID | C6: PERIOD | D6: Unid | E6: Preco bruto (R$/un) | F6: (-) Desconto incond. | G6: (-) Rebate atribuivel | H6: (+) Frete inbound | I6: (+) Seguro | J6: (+) Descarga | K6: (+) Armazenag. | L6: (+) Trib. nao recuperavel | M6: (-) Creditos recuperaveis | N6: LANDED NET (R$/un) | O6: Fator un->t | P6: LANDED NET (R$/t) | Q6: Desembolso financeiro | R6: Credito fiscal | S6: Custo contabil
A7: M001 | B7: S001 | C7: 2026-03 | D7: t | E7: 700 | F7: 20 | G7: 10 | H7: 45 | I7: 3 | J7: 8 | K7: 6 | L7: 0 | M7: 92 | N7: =E7-F7-G7+H7+I7+J7+K7+L7-M7 | O7: =IF(D7="kg",1000,1) | P7: =N7*O7 | Q7: =E7-F7-G7+H7+I7+J7+K7+L7 | R7: =M7 | S7: =N7
A8: M002 | B8: S002 | C8: 2026-03 | D8: t | E8: 55 | F8: 0 | G8: 0 | H8: 22 | I8: 1 | J8: 5 | K8: 3 | L8: 0 | M8: 20 | N8: =E8-F8-G8+H8+I8+J8+K8+L8-M8 | O8: =IF(D8="kg",1000,1) | P8: =N8*O8 | Q8: =E8-F8-G8+H8+I8+J8+K8+L8 | R8: =M8 | S8: =N8
A9: M003 | B9: S001 | C9: 2026-03 | D9: t | E9: 520 | F9: 15 | G9: 0 | H9: 40 | I9: 2 | J9: 6 | K9: 4 | L9: 0 | M9: 72 | N9: =E9-F9-G9+H9+I9+J9+K9+L9-M9 | O9: =IF(D9="kg",1000,1) | P9: =N9*O9 | Q9: =E9-F9-G9+H9+I9+J9+K9+L9 | R9: =M9 | S9: =N9
A10: M004 | B10: S003 | C10: 2026-03 | D10: kg | E10: 19 | F10: 0.4 | G10: 0 | H10: 0.6 | I10: 0.05 | J10: 0.1 | K10: 0.05 | L10: 0 | M10: 2.4 | N10: =E10-F10-G10+H10+I10+J10+K10+L10-M10 | O10: =IF(D10="kg",1000,1) | P10: =N10*O10 | Q10: =E10-F10-G10+H10+I10+J10+K10+L10 | R10: =M10 | S10: =N10
A11: M005 | B11: S003 | C11: 2026-03 | D11: kg | E11: 9.5 | F11: 0.2 | G11: 0 | H11: 0.4 | I11: 0.03 | J11: 0.05 | K11: 0.03 | L11: 0 | M11: 1.2 | N11: =E11-F11-G11+H11+I11+J11+K11+L11-M11 | O11: =IF(D11="kg",1000,1) | P11: =N11*O11 | Q11: =E11-F11-G11+H11+I11+J11+K11+L11 | R11: =M11 | S11: =N11
N12: =E12-F12-G12+H12+I12+J12+K12+L12-M12 | O12: =IF(D12="kg",1000,1) | P12: =N12*O12 | Q12: =E12-F12-G12+H12+I12+J12+K12+L12 | R12: =M12 | S12: =N12
N13: =E13-F13-G13+H13+I13+J13+K13+L13-M13 | O13: =IF(D13="kg",1000,1) | P13: =N13*O13 | Q13: =E13-F13-G13+H13+I13+J13+K13+L13 | R13: =M13 | S13: =N13
N14: =E14-F14-G14+H14+I14+J14+K14+L14-M14 | O14: =IF(D14="kg",1000,1) | P14: =N14*O14 | Q14: =E14-F14-G14+H14+I14+J14+K14+L14 | R14: =M14 | S14: =N14
N15: =E15-F15-G15+H15+I15+J15+K15+L15-M15 | O15: =IF(D15="kg",1000,1) | P15: =N15*O15 | Q15: =E15-F15-G15+H15+I15+J15+K15+L15 | R15: =M15 | S15: =N15
N16: =E16-F16-G16+H16+I16+J16+K16+L16-M16 | O16: =IF(D16="kg",1000,1) | P16: =N16*O16 | Q16: =E16-F16-G16+H16+I16+J16+K16+L16 | R16: =M16 | S16: =N16
N17: =E17-F17-G17+H17+I17+J17+K17+L17-M17 | O17: =IF(D17="kg",1000,1) | P17: =N17*O17 | Q17: =E17-F17-G17+H17+I17+J17+K17+L17 | R17: =M17 | S17: =N17
N18: =E18-F18-G18+H18+I18+J18+K18+L18-M18 | O18: =IF(D18="kg",1000,1) | P18: =N18*O18 | Q18: =E18-F18-G18+H18+I18+J18+K18+L18 | R18: =M18 | S18: =N18
N19: =E19-F19-G19+H19+I19+J19+K19+L19-M19 | O19: =IF(D19="kg",1000,1) | P19: =N19*O19 | Q19: =E19-F19-G19+H19+I19+J19+K19+L19 | R19: =M19 | S19: =N19
N20: =E20-F20-G20+H20+I20+J20+K20+L20-M20 | O20: =IF(D20="kg",1000,1) | P20: =N20*O20 | Q20: =E20-F20-G20+H20+I20+J20+K20+L20 | R20: =M20 | S20: =N20
N21: =E21-F21-G21+H21+I21+J21+K21+L21-M21 | O21: =IF(D21="kg",1000,1) | P21: =N21*O21 | Q21: =E21-F21-G21+H21+I21+J21+K21+L21 | R21: =M21 | S21: =N21
N22: =E22-F22-G22+H22+I22+J22+K22+L22-M22 | O22: =IF(D22="kg",1000,1) | P22: =N22*O22 | Q22: =E22-F22-G22+H22+I22+J22+K22+L22 | R22: =M22 | S22: =N22
N23: =E23-F23-G23+H23+I23+J23+K23+L23-M23 | O23: =IF(D23="kg",1000,1) | P23: =N23*O23 | Q23: =E23-F23-G23+H23+I23+J23+K23+L23 | R23: =M23 | S23: =N23
... N46: =E46-F46-G46+H46+I46+J46+K46+L46-M46 | O46: =IF(D46="kg",1000,1) | P46: =N46*O46 | Q46: =E46-F46-G46+H46+I46+J46+K46+L46 | R46: =M46 | S46: =N46

Sheet 10_TAX_RULES
A1: TAX RULES
A2: Nenhuma aliquota digitada dentro de formula de custo. Cada regra tem vigencia; reforma tributaria (CBS/IBS 2026-2033) por DATA, nunca sobrescrevendo a antiga.
A4: Legenda: | B4: INPUT (editavel) | D4: FORMULA | F4: LINKED (de outra aba) | H4: CONTROL | J4: ALERT | L4: CHAVE/ID
A6: RULE_ID | B6: Tributo | C6: UF | D6: Operacao | E6: NCM | F6: CFOP | G6: CST | H6: Aliq. nominal | I6: Beneficio | J6: % reducao | K6: Aliq. efetiva | L6: Gera credito? | M6: Fundo adic. | N6: Fonte | O6: Responsavel | P6: Vigencia ini | Q6: Vigencia fim | R6: Atualizado em | S6: Comentario
A7: TR001 | B7: ICMS | C7: CE | D7: Saida interna | E7: 3824.50.00 | F7: 5101 | G7: 51 | H7: 0.225 | I7: Reducao 80% | J7: 0.8 | K7: =H7*(1-J7) | L7: Nao | M7: 0
A8: TR002 | B8: ICMS | C8: CE | D8: Entrada MP | E8: 2523.29.10 | F8: 1101 | G8: 00 | H8: 0.18 | I8: Credito integral | J8: 0 | K8: =H8*(1-J8) | L8: Sim | M8: 0
A9: TR003 | B9: PIS | C9: - | D9: Saida | E9: - | F9: - | G9: - | H9: 0.0165 | I9: Nao cumulativo | J9: 0 | K9: =H9*(1-J9) | L9: Sim | M9: 0
A10: TR004 | B10: COFINS | C10: - | D10: Saida | E10: - | F10: - | G10: - | H10: 0.076 | I10: Nao cumulativo | J10: 0 | K10: =H10*(1-J10) | L10: Sim | M10: 0
A11: TR005 | B11: CBS | C11: - | D11: Saida (2027+) | E11: - | F11: - | G11: - | H11: 0 | I11: Reforma - preencher | J11: 0 | K11: =H11*(1-J11) | L11: Sim | M11: 0
A12: TR006 | B12: IBS | C12: - | D12: Saida (2029+) | E12: - | F12: - | G12: - | H12: 0 | I12: Reforma - preencher | J12: 0 | K12: =H12*(1-J12) | L12: Sim | M12: 0
A14: ^ Linhas acima = dados DEMO (marcados). Abaixo: campos de entrada em branco para dados reais.

Sheet 11_TAX_CREDITS
A1: TAX CREDITS
A2: Separar credito potencial, escriturado, utilizado e monetizado. So o efetivamente recuperavel reduz o Landed Net Cost (aba 09).
A4: Legenda: | B4: INPUT (editavel) | D4: FORMULA | F4: LINKED (de outra aba) | H4: CONTROL | J4: ALERT | L4: CHAVE/ID
A6: MATERIAL_ID | B6: PERIOD | C6: Base (R$) | D6: Credito ICMS potencial | E6: Credito PIS/COFINS potencial | F6: Credito escriturado | G6: Credito utilizado | H6: Credito monetizado | I6: Gap (pot.-util.) | J6: Fonte | K6: Responsavel | L6: Vigencia ini | M6: Vigencia fim | N6: Atualizado em | O6: Comentario
A7: M001 | B7: 2026-03 | C7: 100000 | D7: =C7*ICMS_NOMINAL | E7: =C7*(PIS_DEBITO+COFINS_DEBITO) | F7: 0 | G7: 0 | H7: 0 | I7: =D7+E7-G7
A8: M002 | B8: 2026-03 | C8: 50000 | D8: =C8*ICMS_NOMINAL | E8: =C8*(PIS_DEBITO+COFINS_DEBITO) | F8: 0 | G8: 0 | H8: 0 | I8: =D8+E8-G8
A10: ^ Linhas acima = dados DEMO (marcados). Abaixo: campos de entrada em branco para dados reais.

Sheet 15_RESOURCE_RATES
A1: RESOURCE RATES
A2: R$/hora = custo fixo / horas de CAPACIDADE PRATICA (nao a producao real). Base do custo de conversao e do unused capacity cost.
A4: Legenda: | B4: INPUT (editavel) | D4: FORMULA | F4: LINKED (de outra aba) | H4: CONTROL | J4: ALERT | L4: CHAVE/ID
A6: RESOURCE_ID | B6: Custo fixo R$/mes (dep+manut+outros) | C6: Horas praticas/mes | D6: R$/hora pratica
A7: RES-MIST1 | B7: =SUMIF('12_RESOURCES'!$A$7:$A$67,A7,'12_RESOURCES'!$G$7:$G$67)+SUMIF('12_RESOURCES'!$A$7:$A$67,A7,'12_RESOURCES'!$H$7:$H$67)+SUMIF('12_RESOURCES'!$A$7:$A$67,A7,'12_RESOURCES'!$I$7:$I$67) | C7: =SUMIF('12_RESOURCES'!$A$7:$A$67,A7,'12_RESOURCES'!$F$7:$F$67) | D7: =IFERROR(B7/C7,0)
A8: RES-MIST2 | B8: =SUMIF('12_RESOURCES'!$A$7:$A$67,A8,'12_RESOURCES'!$G$7:$G$67)+SUMIF('12_RESOURCES'!$A$7:$A$67,A8,'12_RESOURCES'!$H$7:$H$67)+SUMIF('12_RESOURCES'!$A$7:$A$67,A8,'12_RESOURCES'!$I$7:$I$67) | C8: =SUMIF('12_RESOURCES'!$A$7:$A$67,A8,'12_RESOURCES'!$F$7:$F$67) | D8: =IFERROR(B8/C8,0)

Sheet 16_STANDARD_TIMES
A1: STANDARD TIMES
A2: Consolida o routing (14) em h/t por produto. Base do custo de conversao padrao e do speed loss.
A4: Legenda: | B4: INPUT (editavel) | D4: FORMULA | F4: LINKED (de outra aba) | H4: CONTROL | J4: ALERT | L4: CHAVE/ID
A6: PRODUCT_ID | B6: Tempo padrao total h/t (soma routing) | C6: Velocidade padrao t/h
A7: P001 | B7: =SUMIF('14_ROUTINGS'!$B$7:$B$67,A7,'14_ROUTINGS'!$F$7:$F$67) | C7: =IFERROR(1/B7,0)
A8: P002 | B8: =SUMIF('14_ROUTINGS'!$B$7:$B$67,A8,'14_ROUTINGS'!$F$7:$F$67) | C8: =IFERROR(1/B8,0)
A9: P003 | B9: =SUMIF('14_ROUTINGS'!$B$7:$B$67,A9,'14_ROUTINGS'!$F$7:$F$67) | C9: =IFERROR(1/B9,0)

Sheet 17_PRODUCTION_OF
A1: PRODUCTION OF
A2: Produtividade medida por hora inicio/fim da OF/lote (NAO por jornada contratual). Reproc. separado. t/h = qtd boa / tempo.
A4: Legenda: | B4: INPUT (editavel) | D4: FORMULA | F4: LINKED (de outra aba) | H4: CONTROL | J4: ALERT | L4: CHAVE/ID
A6: OF_ID | B6: PRODUCT_ID | C6: FORMULA_ID | D6: Versao | E6: RESOURCE_ID | F6: Equipe | G6: Data | H6: Hora ini | I6: Hora fim | J6: Qtd progr. (t) | K6: Qtd produz. (t) | L6: Qtd BOA (t) | M6: Sacos | N6: Paletes | O6: Perdas (t) | P6: Reproc. (t) | Q6: Tempo (h) | R6: t/h | S6: Obs
A7: OF-2603-01 | B7: P001 | C7: F-P001 | D7: v1 | E7: RES-MIST1 | F7: Turma A | G7: 2026-03-05 | H7: 06:00 | I7: 10:00 | J7: 400 | K7: 402 | L7: 400 | M7: =IFERROR(L7*1000/INDEX('03_PRODUCTS'!$G$7:$G$49,MATCH(B7,'03_PRODUCTS'!$A$7:$A$49,0)),"") | N7: =IFERROR(M7/INDEX('03_PRODUCTS'!$H$7:$H$49,MATCH(B7,'03_PRODUCTS'!$A$7:$A$49,0)),"") | O7: =K7-L7-P7 | P7: 0 | Q7: =IFERROR((TIMEVALUE(I7)-TIMEVALUE(H7))*24,"") | R7: =IFERROR(L7/Q7,"")
A8: OF-2603-02 | B8: P002 | C8: F-P002 | D8: v1 | E8: RES-MIST1 | F8: Turma A | G8: 2026-03-06 | H8: 06:00 | I8: 11:00 | J8: 250 | K8: 251 | L8: 250 | M8: =IFERROR(L8*1000/INDEX('03_PRODUCTS'!$G$7:$G$49,MATCH(B8,'03_PRODUCTS'!$A$7:$A$49,0)),"") | N8: =IFERROR(M8/INDEX('03_PRODUCTS'!$H$7:$H$49,MATCH(B8,'03_PRODUCTS'!$A$7:$A$49,0)),"") | O8: =K8-L8-P8 | P8: 0 | Q8: =IFERROR((TIMEVALUE(I8)-TIMEVALUE(H8))*24,"") | R8: =IFERROR(L8/Q8,"")
A9: OF-2603-03 | B9: P003 | C9: F-P003 | D9: v1 | E9: RES-MIST2 | F9: Turma B | G9: 2026-03-07 | H9: 07:00 | I9: 10:00 | J9: 120 | K9: 121 | L9: 120 | M9: =IFERROR(L9*1000/INDEX('03_PRODUCTS'!$G$7:$G$49,MATCH(B9,'03_PRODUCTS'!$A$7:$A$49,0)),"") | N9: =IFERROR(M9/INDEX('03_PRODUCTS'!$H$7:$H$49,MATCH(B9,'03_PRODUCTS'!$A$7:$A$49,0)),"") | O9: =K9-L9-P9 | P9: 0.5 | Q9: =IFERROR((TIMEVALUE(I9)-TIMEVALUE(H9))*24,"") | R9: =IFERROR(L9/Q9,"")

Sheet 18_ACTUAL_CONSUMPTION
A1: ACTUAL CONSUMPTION
A2: Base do Actual Cost. Act qtd = act kg/t /1000 x good tons. Act custo = act qtd x act preco.
A4: Legenda: | B4: INPUT (editavel) | D4: FORMULA | F4: LINKED (de outra aba) | H4: CONTROL | J4: ALERT | L4: CHAVE/ID
A6: OF_ID | B6: PRODUCT_ID | C6: MATERIAL_ID | D6: Good tons (link) | E6: Act kg/t (real) | F6: Act qtd (t) | G6: Act preco R$/t (real) | H6: Act custo (R$) | I6: KEY (prod|mat)
A7: OF-2603-01 | B7: P001 | C7: M001 | D7: =IFERROR(INDEX('17_PRODUCTION_OF'!$L$7:$L$47,MATCH(A7,'17_PRODUCTION_OF'!$A$7:$A$47,0)),0) | E7: 255 | F7: =E7/1000*D7 | G7: 660 | H7: =F7*G7 | I7: =B7&"|"&C7
A8: OF-2603-01 | B8: P001 | C8: M002 | D8: =IFERROR(INDEX('17_PRODUCTION_OF'!$L$7:$L$47,MATCH(A8,'17_PRODUCTION_OF'!$A$7:$A$47,0)),0) | E8: 700 | F8: =E8/1000*D8 | G8: 66 | H8: =F8*G8 | I8: =B8&"|"&C8
A9: OF-2603-01 | B9: P001 | C9: M003 | D9: =IFERROR(INDEX('17_PRODUCTION_OF'!$L$7:$L$47,MATCH(A9,'17_PRODUCTION_OF'!$A$7:$A$47,0)),0) | E9: 45 | F9: =E9/1000*D9 | G9: 485 | H9: =F9*G9 | I9: =B9&"|"&C9
A10: OF-2603-01 | B10: P001 | C10: M004 | D10: =IFERROR(INDEX('17_PRODUCTION_OF'!$L$7:$L$47,MATCH(A10,'17_PRODUCTION_OF'!$A$7:$A$47,0)),0) | E10: 5 | F10: =E10/1000*D10 | G10: 17000 | H10: =F10*G10 | I10: =B10&"|"&C10
A11: OF-2603-02 | B11: P002 | C11: M001 | D11: =IFERROR(INDEX('17_PRODUCTION_OF'!$L$7:$L$47,MATCH(A11,'17_PRODUCTION_OF'!$A$7:$A$47,0)),0) | E11: 300 | F11: =E11/1000*D11 | G11: 660 | H11: =F11*G11 | I11: =B11&"|"&C11
A12: OF-2603-02 | B12: P002 | C12: M002 | D12: =IFERROR(INDEX('17_PRODUCTION_OF'!$L$7:$L$47,MATCH(A12,'17_PRODUCTION_OF'!$A$7:$A$47,0)),0) | E12: 655 | F12: =E12/1000*D12 | G12: 66 | H12: =F12*G12 | I12: =B12&"|"&C12
A13: OF-2603-02 | B13: P002 | C13: M003 | D13: =IFERROR(INDEX('17_PRODUCTION_OF'!$L$7:$L$47,MATCH(A13,'17_PRODUCTION_OF'!$A$7:$A$47,0)),0) | E13: 45 | F13: =E13/1000*D13 | G13: 485 | H13: =F13*G13 | I13: =B13&"|"&C13
A14: OF-2603-02 | B14: P002 | C14: M004 | D14: =IFERROR(INDEX('17_PRODUCTION_OF'!$L$7:$L$47,MATCH(A14,'17_PRODUCTION_OF'!$A$7:$A$47,0)),0) | E14: 5 | F14: =E14/1000*D14 | G14: 17000 | H14: =F14*G14 | I14: =B14&"|"&C14
A15: OF-2603-03 | B15: P003 | C15: M001 | D15: =IFERROR(INDEX('17_PRODUCTION_OF'!$L$7:$L$47,MATCH(A15,'17_PRODUCTION_OF'!$A$7:$A$47,0)),0) | E15: 350 | F15: =E15/1000*D15 | G15: 660 | H15: =F15*G15 | I15: =B15&"|"&C15
A16: OF-2603-03 | B16: P003 | C16: M002 | D16: =IFERROR(INDEX('17_PRODUCTION_OF'!$L$7:$L$47,MATCH(A16,'17_PRODUCTION_OF'!$A$7:$A$47,0)),0) | E16: 600 | F16: =E16/1000*D16 | G16: 66 | H16: =F16*G16 | I16: =B16&"|"&C16
A17: OF-2603-03 | B17: P003 | C17: M004 | D17: =IFERROR(INDEX('17_PRODUCTION_OF'!$L$7:$L$47,MATCH(A17,'17_PRODUCTION_OF'!$A$7:$A$47,0)),0) | E17: 8 | F17: =E17/1000*D17 | G17: 17000 | H17: =F17*G17 | I17: =B17&"|"&C17
A18: OF-2603-03 | B18: P003 | C18: M005 | D18: =IFERROR(INDEX('17_PRODUCTION_OF'!$L$7:$L$47,MATCH(A18,'17_PRODUCTION_OF'!$A$7:$A$47,0)),0) | E18: 42 | F18: =E18/1000*D18 | G18: 8610 | H18: =F18*G18 | I18: =B18&"|"&C18
D19: =IF(A19="","",IFERROR(INDEX('17_PRODUCTION_OF'!$L$7:$L$47,MATCH(A19,'17_PRODUCTION_OF'!$A$7:$A$47,0)),0)) | F19: =IF(E19="","",E19/1000*D19) | H19: =IF(F19="","",F19*G19) | I19: =IF(B19="","",B19&"|"&C19)
D20: =IF(A20="","",IFERROR(INDEX('17_PRODUCTION_OF'!$L$7:$L$47,MATCH(A20,'17_PRODUCTION_OF'!$A$7:$A$47,0)),0)) | F20: =IF(E20="","",E20/1000*D20) | H20: =IF(F20="","",F20*G20) | I20: =IF(B20="","",B20&"|"&C20)
D21: =IF(A21="","",IFERROR(INDEX('17_PRODUCTION_OF'!$L$7:$L$47,MATCH(A21,'17_PRODUCTION_OF'!$A$7:$A$47,0)),0)) | F21: =IF(E21="","",E21/1000*D21) | H21: =IF(F21="","",F21*G21) | I21: =IF(B21="","",B21&"|"&C21)
D22: =IF(A22="","",IFERROR(INDEX('17_PRODUCTION_OF'!$L$7:$L$47,MATCH(A22,'17_PRODUCTION_OF'!$A$7:$A$47,0)),0)) | F22: =IF(E22="","",E22/1000*D22) | H22: =IF(F22="","",F22*G22) | I22: =IF(B22="","",B22&"|"&C22)
D23: =IF(A23="","",IFERROR(INDEX('17_PRODUCTION_OF'!$L$7:$L$47,MATCH(A23,'17_PRODUCTION_OF'!$A$7:$A$47,0)),0)) | F23: =IF(E23="","",E23/1000*D23) | H23: =IF(F23="","",F23*G23) | I23: =IF(B23="","",B23&"|"&C23)
D24: =IF(A24="","",IFERROR(INDEX('17_PRODUCTION_OF'!$L$7:$L$47,MATCH(A24,'17_PRODUCTION_OF'!$A$7:$A$47,0)),0)) | F24: =IF(E24="","",E24/1000*D24) | H24: =IF(F24="","",F24*G24) | I24: =IF(B24="","",B24&"|"&C24)
D25: =IF(A25="","",IFERROR(INDEX('17_PRODUCTION_OF'!$L$7:$L$47,MATCH(A25,'17_PRODUCTION_OF'!$A$7:$A$47,0)),0)) | F25: =IF(E25="","",E25/1000*D25) | H25: =IF(F25="","",F25*G25) | I25: =IF(B25="","",B25&"|"&C25)
D26: =IF(A26="","",IFERROR(INDEX('17_PRODUCTION_OF'!$L$7:$L$47,MATCH(A26,'17_PRODUCTION_OF'!$A$7:$A$47,0)),0)) | F26: =IF(E26="","",E26/1000*D26) | H26: =IF(F26="","",F26*G26) | I26: =IF(B26="","",B26&"|"&C26)
D27: =IF(A27="","",IFERROR(INDEX('17_PRODUCTION_OF'!$L$7:$L$47,MATCH(A27,'17_PRODUCTION_OF'!$A$7:$A$47,0)),0)) | F27: =IF(E27="","",E27/1000*D27) | H27: =IF(F27="","",F27*G27) | I27: =IF(B27="","",B27&"|"&C27)
D28: =IF(A28="","",IFERROR(INDEX('17_PRODUCTION_OF'!$L$7:$L$47,MATCH(A28,'17_PRODUCTION_OF'!$A$7:$A$47,0)),0)) | F28: =IF(E28="","",E28/1000*D28) | H28: =IF(F28="","",F28*G28) | I28: =IF(B28="","",B28&"|"&C28)
D29: =IF(A29="","",IFERROR(INDEX('17_PRODUCTION_OF'!$L$7:$L$47,MATCH(A29,'17_PRODUCTION_OF'!$A$7:$A$47,0)),0)) | F29: =IF(E29="","",E29/1000*D29) | H29: =IF(F29="","",F29*G29) | I29: =IF(B29="","",B29&"|"&C29)
D30: =IF(A30="","",IFERROR(INDEX('17_PRODUCTION_OF'!$L$7:$L$47,MATCH(A30,'17_PRODUCTION_OF'!$A$7:$A$47,0)),0)) | F30: =IF(E30="","",E30/1000*D30) | H30: =IF(F30="","",F30*G30) | I30: =IF(B30="","",B30&"|"&C30)
... D66: =IF(A66="","",IFERROR(INDEX('17_PRODUCTION_OF'!$L$7:$L$47,MATCH(A66,'17_PRODUCTION_OF'!$A$7:$A$47,0)),0)) | F66: =IF(E66="","",E66/1000*D66) | H66: =IF(F66="","",F66*G66) | I66: =IF(B66="","",B66&"|"&C66)

Sheet 26_STANDARD_COST
A1: STANDARD COST
A2: Material std = SUMIF do BOM (kg/t x landed R$/t). Conversao std vem do routing (input aqui). Unidade base: R$/tonelada boa produzida.
A4: Legenda: | B4: INPUT (editavel) | D4: FORMULA | F4: LINKED (de outra aba) | H4: CONTROL | J4: ALERT | L4: CHAVE/ID
A6: PRODUCT_ID | B6: Descricao | C6: Good tons (link OF) | D6: Material std R$/t | E6: Conversao std R$/t | F6: TOTAL STD R$/t | G6: TOTAL STD R$
A7: P001 | B7: Multiuso | C7: =SUMIF('17_PRODUCTION_OF'!$B$7:$B$47,A7,'17_PRODUCTION_OF'!$L$7:$L$47) | D7: =SUMIF('06_BOM'!$A$7:$A$67,A7,'06_BOM'!$L$7:$L$67) | E7: 38 | F7: =D7+E7 | G7: =F7*C7
A8: P002 | B8: Argamassa AC-III | C8: =SUMIF('17_PRODUCTION_OF'!$B$7:$B$47,A8,'17_PRODUCTION_OF'!$L$7:$L$47) | D8: =SUMIF('06_BOM'!$A$7:$A$67,A8,'06_BOM'!$L$7:$L$67) | E8: 42 | F8: =D8+E8 | G8: =F8*C8
A9: P003 | B9: Rejunte | C9: =SUMIF('17_PRODUCTION_OF'!$B$7:$B$47,A9,'17_PRODUCTION_OF'!$L$7:$L$47) | D9: =SUMIF('06_BOM'!$A$7:$A$67,A9,'06_BOM'!$L$7:$L$67) | E9: 55 | F9: =D9+E9 | G9: =F9*C9

Sheet 27_ACTUAL_COST
A1: ACTUAL COST
A2: Material real = SUMIFS de 18_ACTUAL_CONSUMPTION. Conversao real (input; origem apontamento). TOTAL ACT R$/t e o KPI Material+Conversao por tonelada boa.
A4: Legenda: | B4: INPUT (editavel) | D4: FORMULA | F4: LINKED (de outra aba) | H4: CONTROL | J4: ALERT | L4: CHAVE/ID
A6: PRODUCT_ID | B6: Good tons (link) | C6: Material act R$ | D6: Material act R$/t | E6: Conversao act R$/t | F6: Conversao act R$ | G6: TOTAL ACT R$ | H6: TOTAL ACT R$/t
A7: P001 | B7: =SUMIF('17_PRODUCTION_OF'!$B$7:$B$47,A7,'17_PRODUCTION_OF'!$L$7:$L$47) | C7: =SUMIF('18_ACTUAL_CONSUMPTION'!$B$7:$B$67,A7,'18_ACTUAL_CONSUMPTION'!$H$7:$H$67) | D7: =IFERROR(C7/B7,0) | E7: 41 | F7: =E7*B7 | G7: =C7+F7 | H7: =IFERROR(G7/B7,0)
A8: P002 | B8: =SUMIF('17_PRODUCTION_OF'!$B$7:$B$47,A8,'17_PRODUCTION_OF'!$L$7:$L$47) | C8: =SUMIF('18_ACTUAL_CONSUMPTION'!$B$7:$B$67,A8,'18_ACTUAL_CONSUMPTION'!$H$7:$H$67) | D8: =IFERROR(C8/B8,0) | E8: 42 | F8: =E8*B8 | G8: =C8+F8 | H8: =IFERROR(G8/B8,0)
A9: P003 | B9: =SUMIF('17_PRODUCTION_OF'!$B$7:$B$47,A9,'17_PRODUCTION_OF'!$L$7:$L$47) | C9: =SUMIF('18_ACTUAL_CONSUMPTION'!$B$7:$B$67,A9,'18_ACTUAL_CONSUMPTION'!$H$7:$H$67) | D9: =IFERROR(C9/B9,0) | E9: 58 | F9: =E9*B9 | G9: =C9+F9 | H9: =IFERROR(G9/B9,0)

Sheet 28_VARIANCES
A1: VARIANCES
A2: PPV=(Act-Std preco)xAct qtd ; Usage=(Act-Std qtd)xStd preco. Std cost + PPV + Usage = Act cost (Residual->0). Mix/Yield e conversao no bloco resumo.
A4: Legenda: | B4: INPUT (editavel) | D4: FORMULA | F4: LINKED (de outra aba) | H4: CONTROL | J4: ALERT | L4: CHAVE/ID
A6: PRODUCT_ID | B6: MATERIAL_ID | C6: Good tons | D6: Std kg/t | E6: Act kg/t | F6: Std R$/t | G6: Act R$/t | H6: Std qtd (t) | I6: Act qtd (t) | J6: Std cost R$ | K6: Act cost R$ | L6: PPV R$ | M6: Usage R$ | N6: Residual
A7: P001 | B7: M001 | C7: =SUMIF('17_PRODUCTION_OF'!$B$7:$B$47,A7,'17_PRODUCTION_OF'!$L$7:$L$47) | D7: =IFERROR(INDEX('06_BOM'!$E$7:$E$67,MATCH(A7&"|"&B7,'06_BOM'!$M$7:$M$67,0)),0) | E7: =IFERROR(INDEX('18_ACTUAL_CONSUMPTION'!$E$7:$E$67,MATCH(A7&"|"&B7,'18_ACTUAL_CONSUMPTION'!$I$7:$I$67,0)),0) | F7: =IFERROR(INDEX('09_LANDED_COST'!$P$7:$P$47,MATCH(B7,'09_LANDED_COST'!$A$7:$A$47,0)),0) | G7: =IFERROR(INDEX('18_ACTUAL_CONSUMPTION'!$G$7:$G$67,MATCH(A7&"|"&B7,'18_ACTUAL_CONSUMPTION'!$I$7:$I$67,0)),0) | H7: =D7/1000*C7 | I7: =E7/1000*C7 | J7: =H7*F7 | K7: =I7*G7 | L7: =(G7-F7)*I7 | M7: =(I7-H7)*F7 | N7: =K7-J7-L7-M7
A8: P001 | B8: M002 | C8: =SUMIF('17_PRODUCTION_OF'!$B$7:$B$47,A8,'17_PRODUCTION_OF'!$L$7:$L$47) | D8: =IFERROR(INDEX('06_BOM'!$E$7:$E$67,MATCH(A8&"|"&B8,'06_BOM'!$M$7:$M$67,0)),0) | E8: =IFERROR(INDEX('18_ACTUAL_CONSUMPTION'!$E$7:$E$67,MATCH(A8&"|"&B8,'18_ACTUAL_CONSUMPTION'!$I$7:$I$67,0)),0) | F8: =IFERROR(INDEX('09_LANDED_COST'!$P$7:$P$47,MATCH(B8,'09_LANDED_COST'!$A$7:$A$47,0)),0) | G8: =IFERROR(INDEX('18_ACTUAL_CONSUMPTION'!$G$7:$G$67,MATCH(A8&"|"&B8,'18_ACTUAL_CONSUMPTION'!$I$7:$I$67,0)),0) | H8: =D8/1000*C8 | I8: =E8/1000*C8 | J8: =H8*F8 | K8: =I8*G8 | L8: =(G8-F8)*I8 | M8: =(I8-H8)*F8 | N8: =K8-J8-L8-M8
A9: P001 | B9: M003 | C9: =SUMIF('17_PRODUCTION_OF'!$B$7:$B$47,A9,'17_PRODUCTION_OF'!$L$7:$L$47) | D9: =IFERROR(INDEX('06_BOM'!$E$7:$E$67,MATCH(A9&"|"&B9,'06_BOM'!$M$7:$M$67,0)),0) | E9: =IFERROR(INDEX('18_ACTUAL_CONSUMPTION'!$E$7:$E$67,MATCH(A9&"|"&B9,'18_ACTUAL_CONSUMPTION'!$I$7:$I$67,0)),0) | F9: =IFERROR(INDEX('09_LANDED_COST'!$P$7:$P$47,MATCH(B9,'09_LANDED_COST'!$A$7:$A$47,0)),0) | G9: =IFERROR(INDEX('18_ACTUAL_CONSUMPTION'!$G$7:$G$67,MATCH(A9&"|"&B9,'18_ACTUAL_CONSUMPTION'!$I$7:$I$67,0)),0) | H9: =D9/1000*C9 | I9: =E9/1000*C9 | J9: =H9*F9 | K9: =I9*G9 | L9: =(G9-F9)*I9 | M9: =(I9-H9)*F9 | N9: =K9-J9-L9-M9
A10: P001 | B10: M004 | C10: =SUMIF('17_PRODUCTION_OF'!$B$7:$B$47,A10,'17_PRODUCTION_OF'!$L$7:$L$47) | D10: =IFERROR(INDEX('06_BOM'!$E$7:$E$67,MATCH(A10&"|"&B10,'06_BOM'!$M$7:$M$67,0)),0) | E10: =IFERROR(INDEX('18_ACTUAL_CONSUMPTION'!$E$7:$E$67,MATCH(A10&"|"&B10,'18_ACTUAL_CONSUMPTION'!$I$7:$I$67,0)),0) | F10: =IFERROR(INDEX('09_LANDED_COST'!$P$7:$P$47,MATCH(B10,'09_LANDED_COST'!$A$7:$A$47,0)),0) | G10: =IFERROR(INDEX('18_ACTUAL_CONSUMPTION'!$G$7:$G$67,MATCH(A10&"|"&B10,'18_ACTUAL_CONSUMPTION'!$I$7:$I$67,0)),0) | H10: =D10/1000*C10 | I10: =E10/1000*C10 | J10: =H10*F10 | K10: =I10*G10 | L10: =(G10-F10)*I10 | M10: =(I10-H10)*F10 | N10: =K10-J10-L10-M10
A11: P002 | B11: M001 | C11: =SUMIF('17_PRODUCTION_OF'!$B$7:$B$47,A11,'17_PRODUCTION_OF'!$L$7:$L$47) | D11: =IFERROR(INDEX('06_BOM'!$E$7:$E$67,MATCH(A11&"|"&B11,'06_BOM'!$M$7:$M$67,0)),0) | E11: =IFERROR(INDEX('18_ACTUAL_CONSUMPTION'!$E$7:$E$67,MATCH(A11&"|"&B11,'18_ACTUAL_CONSUMPTION'!$I$7:$I$67,0)),0) | F11: =IFERROR(INDEX('09_LANDED_COST'!$P$7:$P$47,MATCH(B11,'09_LANDED_COST'!$A$7:$A$47,0)),0) | G11: =IFERROR(INDEX('18_ACTUAL_CONSUMPTION'!$G$7:$G$67,MATCH(A11&"|"&B11,'18_ACTUAL_CONSUMPTION'!$I$7:$I$67,0)),0) | H11: =D11/1000*C11 | I11: =E11/1000*C11 | J11: =H11*F11 | K11: =I11*G11 | L11: =(G11-F11)*I11 | M11: =(I11-H11)*F11 | N11: =K11-J11-L11-M11
A12: P002 | B12: M002 | C12: =SUMIF('17_PRODUCTION_OF'!$B$7:$B$47,A12,'17_PRODUCTION_OF'!$L$7:$L$47) | D12: =IFERROR(INDEX('06_BOM'!$E$7:$E$67,MATCH(A12&"|"&B12,'06_BOM'!$M$7:$M$67,0)),0) | E12: =IFERROR(INDEX('18_ACTUAL_CONSUMPTION'!$E$7:$E$67,MATCH(A12&"|"&B12,'18_ACTUAL_CONSUMPTION'!$I$7:$I$67,0)),0) | F12: =IFERROR(INDEX('09_LANDED_COST'!$P$7:$P$47,MATCH(B12,'09_LANDED_COST'!$A$7:$A$47,0)),0) | G12: =IFERROR(INDEX('18_ACTUAL_CONSUMPTION'!$G$7:$G$67,MATCH(A12&"|"&B12,'18_ACTUAL_CONSUMPTION'!$I$7:$I$67,0)),0) | H12: =D12/1000*C12 | I12: =E12/1000*C12 | J12: =H12*F12 | K12: =I12*G12 | L12: =(G12-F12)*I12 | M12: =(I12-H12)*F12 | N12: =K12-J12-L12-M12
A13: P002 | B13: M003 | C13: =SUMIF('17_PRODUCTION_OF'!$B$7:$B$47,A13,'17_PRODUCTION_OF'!$L$7:$L$47) | D13: =IFERROR(INDEX('06_BOM'!$E$7:$E$67,MATCH(A13&"|"&B13,'06_BOM'!$M$7:$M$67,0)),0) | E13: =IFERROR(INDEX('18_ACTUAL_CONSUMPTION'!$E$7:$E$67,MATCH(A13&"|"&B13,'18_ACTUAL_CONSUMPTION'!$I$7:$I$67,0)),0) | F13: =IFERROR(INDEX('09_LANDED_COST'!$P$7:$P$47,MATCH(B13,'09_LANDED_COST'!$A$7:$A$47,0)),0) | G13: =IFERROR(INDEX('18_ACTUAL_CONSUMPTION'!$G$7:$G$67,MATCH(A13&"|"&B13,'18_ACTUAL_CONSUMPTION'!$I$7:$I$67,0)),0) | H13: =D13/1000*C13 | I13: =E13/1000*C13 | J13: =H13*F13 | K13: =I13*G13 | L13: =(G13-F13)*I13 | M13: =(I13-H13)*F13 | N13: =K13-J13-L13-M13
A14: P002 | B14: M004 | C14: =SUMIF('17_PRODUCTION_OF'!$B$7:$B$47,A14,'17_PRODUCTION_OF'!$L$7:$L$47) | D14: =IFERROR(INDEX('06_BOM'!$E$7:$E$67,MATCH(A14&"|"&B14,'06_BOM'!$M$7:$M$67,0)),0) | E14: =IFERROR(INDEX('18_ACTUAL_CONSUMPTION'!$E$7:$E$67,MATCH(A14&"|"&B14,'18_ACTUAL_CONSUMPTION'!$I$7:$I$67,0)),0) | F14: =IFERROR(INDEX('09_LANDED_COST'!$P$7:$P$47,MATCH(B14,'09_LANDED_COST'!$A$7:$A$47,0)),0) | G14: =IFERROR(INDEX('18_ACTUAL_CONSUMPTION'!$G$7:$G$67,MATCH(A14&"|"&B14,'18_ACTUAL_CONSUMPTION'!$I$7:$I$67,0)),0) | H14: =D14/1000*C14 | I14: =E14/1000*C14 | J14: =H14*F14 | K14: =I14*G14 | L14: =(G14-F14)*I14 | M14: =(I14-H14)*F14 | N14: =K14-J14-L14-M14
A15: P003 | B15: M001 | C15: =SUMIF('17_PRODUCTION_OF'!$B$7:$B$47,A15,'17_PRODUCTION_OF'!$L$7:$L$47) | D15: =IFERROR(INDEX('06_BOM'!$E$7:$E$67,MATCH(A15&"|"&B15,'06_BOM'!$M$7:$M$67,0)),0) | E15: =IFERROR(INDEX('18_ACTUAL_CONSUMPTION'!$E$7:$E$67,MATCH(A15&"|"&B15,'18_ACTUAL_CONSUMPTION'!$I$7:$I$67,0)),0) | F15: =IFERROR(INDEX('09_LANDED_COST'!$P$7:$P$47,MATCH(B15,'09_LANDED_COST'!$A$7:$A$47,0)),0) | G15: =IFERROR(INDEX('18_ACTUAL_CONSUMPTION'!$G$7:$G$67,MATCH(A15&"|"&B15,'18_ACTUAL_CONSUMPTION'!$I$7:$I$67,0)),0) | H15: =D15/1000*C15 | I15: =E15/1000*C15 | J15: =H15*F15 | K15: =I15*G15 | L15: =(G15-F15)*I15 | M15: =(I15-H15)*F15 | N15: =K15-J15-L15-M15
A16: P003 | B16: M002 | C16: =SUMIF('17_PRODUCTION_OF'!$B$7:$B$47,A16,'17_PRODUCTION_OF'!$L$7:$L$47) | D16: =IFERROR(INDEX('06_BOM'!$E$7:$E$67,MATCH(A16&"|"&B16,'06_BOM'!$M$7:$M$67,0)),0) | E16: =IFERROR(INDEX('18_ACTUAL_CONSUMPTION'!$E$7:$E$67,MATCH(A16&"|"&B16,'18_ACTUAL_CONSUMPTION'!$I$7:$I$67,0)),0) | F16: =IFERROR(INDEX('09_LANDED_COST'!$P$7:$P$47,MATCH(B16,'09_LANDED_COST'!$A$7:$A$47,0)),0) | G16: =IFERROR(INDEX('18_ACTUAL_CONSUMPTION'!$G$7:$G$67,MATCH(A16&"|"&B16,'18_ACTUAL_CONSUMPTION'!$I$7:$I$67,0)),0) | H16: =D16/1000*C16 | I16: =E16/1000*C16 | J16: =H16*F16 | K16: =I16*G16 | L16: =(G16-F16)*I16 | M16: =(I16-H16)*F16 | N16: =K16-J16-L16-M16
A17: P003 | B17: M004 | C17: =SUMIF('17_PRODUCTION_OF'!$B$7:$B$47,A17,'17_PRODUCTION_OF'!$L$7:$L$47) | D17: =IFERROR(INDEX('06_BOM'!$E$7:$E$67,MATCH(A17&"|"&B17,'06_BOM'!$M$7:$M$67,0)),0) | E17: =IFERROR(INDEX('18_ACTUAL_CONSUMPTION'!$E$7:$E$67,MATCH(A17&"|"&B17,'18_ACTUAL_CONSUMPTION'!$I$7:$I$67,0)),0) | F17: =IFERROR(INDEX('09_LANDED_COST'!$P$7:$P$47,MATCH(B17,'09_LANDED_COST'!$A$7:$A$47,0)),0) | G17: =IFERROR(INDEX('18_ACTUAL_CONSUMPTION'!$G$7:$G$67,MATCH(A17&"|"&B17,'18_ACTUAL_CONSUMPTION'!$I$7:$I$67,0)),0) | H17: =D17/1000*C17 | I17: =E17/1000*C17 | J17: =H17*F17 | K17: =I17*G17 | L17: =(G17-F17)*I17 | M17: =(I17-H17)*F17 | N17: =K17-J17-L17-M17
A18: P003 | B18: M005 | C18: =SUMIF('17_PRODUCTION_OF'!$B$7:$B$47,A18,'17_PRODUCTION_OF'!$L$7:$L$47) | D18: =IFERROR(INDEX('06_BOM'!$E$7:$E$67,MATCH(A18&"|"&B18,'06_BOM'!$M$7:$M$67,0)),0) | E18: =IFERROR(INDEX('18_ACTUAL_CONSUMPTION'!$E$7:$E$67,MATCH(A18&"|"&B18,'18_ACTUAL_CONSUMPTION'!$I$7:$I$67,0)),0) | F18: =IFERROR(INDEX('09_LANDED_COST'!$P$7:$P$47,MATCH(B18,'09_LANDED_COST'!$A$7:$A$47,0)),0) | G18: =IFERROR(INDEX('18_ACTUAL_CONSUMPTION'!$G$7:$G$67,MATCH(A18&"|"&B18,'18_ACTUAL_CONSUMPTION'!$I$7:$I$67,0)),0) | H18: =D18/1000*C18 | I18: =E18/1000*C18 | J18: =H18*F18 | K18: =I18*G18 | L18: =(G18-F18)*I18 | M18: =(I18-H18)*F18 | N18: =K18-J18-L18-M18
A21: RESUMO POR PRODUTO — MIX/YIELD, CONVERSAO E RECONCILIACAO
A22: PRODUCT_ID | B22: Std mat R$ | C22: Act mat R$ | D22: PPV R$ | E22: Usage R$ | F22: Std qtd T | G22: Act qtd T | H22: wsp R$/t | I22: Yield R$ | J22: Mix R$ | K22: Conv var R$ | L22: Total var R$ | M22: Recon check
A23: P001 | B23: =SUMIF($A$7:$A$18,A23,$J$7:$J$18) | C23: =SUMIF($A$7:$A$18,A23,$K$7:$K$18) | D23: =SUMIF($A$7:$A$18,A23,$L$7:$L$18) | E23: =SUMIF($A$7:$A$18,A23,$M$7:$M$18) | F23: =SUMIF($A$7:$A$18,A23,$H$7:$H$18) | G23: =SUMIF($A$7:$A$18,A23,$I$7:$I$18) | H23: =IFERROR(B23/F23,0) | I23: =(G23-F23)*H23 | J23: =E23-I23 | K23: =(INDEX('27_ACTUAL_COST'!$E$7:$E$9,MATCH(A23,'27_ACTUAL_COST'!$A$7:$A$9,0))-INDEX('26_STANDARD_COST'!$E$7:$E$9,MATCH(A23,'26_STANDARD_COST'!$A$7:$A$9,0)))*INDEX('26_STANDARD_COST'!$C$7:$C$9,MATCH(A23,'26_STANDARD_COST'!$A$7:$A$9,0)) | L23: =D23+E23+K23 | M23: =ROUND(INDEX('26_STANDARD_COST'!$G$7:$G$9,MATCH(A23,'26_STANDARD_COST'!$A$7:$A$9,0))+L23-INDEX('27_ACTUAL_COST'!$G$7:$G$9,MATCH(A23,'27_ACTUAL_COST'!$A$7:$A$9,0)),2)
A24: P002 | B24: =SUMIF($A$7:$A$18,A24,$J$7:$J$18) | C24: =SUMIF($A$7:$A$18,A24,$K$7:$K$18) | D24: =SUMIF($A$7:$A$18,A24,$L$7:$L$18) | E24: =SUMIF($A$7:$A$18,A24,$M$7:$M$18) | F24: =SUMIF($A$7:$A$18,A24,$H$7:$H$18) | G24: =SUMIF($A$7:$A$18,A24,$I$7:$I$18) | H24: =IFERROR(B24/F24,0) | I24: =(G24-F24)*H24 | J24: =E24-I24 | K24: =(INDEX('27_ACTUAL_COST'!$E$7:$E$9,MATCH(A24,'27_ACTUAL_COST'!$A$7:$A$9,0))-INDEX('26_STANDARD_COST'!$E$7:$E$9,MATCH(A24,'26_STANDARD_COST'!$A$7:$A$9,0)))*INDEX('26_STANDARD_COST'!$C$7:$C$9,MATCH(A24,'26_STANDARD_COST'!$A$7:$A$9,0)) | L24: =D24+E24+K24 | M24: =ROUND(INDEX('26_STANDARD_COST'!$G$7:$G$9,MATCH(A24,'26_STANDARD_COST'!$A$7:$A$9,0))+L24-INDEX('27_ACTUAL_COST'!$G$7:$G$9,MATCH(A24,'27_ACTUAL_COST'!$A$7:$A$9,0)),2)
A25: P003 | B25: =SUMIF($A$7:$A$18,A25,$J$7:$J$18) | C25: =SUMIF($A$7:$A$18,A25,$K$7:$K$18) | D25: =SUMIF($A$7:$A$18,A25,$L$7:$L$18) | E25: =SUMIF($A$7:$A$18,A25,$M$7:$M$18) | F25: =SUMIF($A$7:$A$18,A25,$H$7:$H$18) | G25: =SUMIF($A$7:$A$18,A25,$I$7:$I$18) | H25: =IFERROR(B25/F25,0) | I25: =(G25-F25)*H25 | J25: =E25-I25 | K25: =(INDEX('27_ACTUAL_COST'!$E$7:$E$9,MATCH(A25,'27_ACTUAL_COST'!$A$7:$A$9,0))-INDEX('26_STANDARD_COST'!$E$7:$E$9,MATCH(A25,'26_STANDARD_COST'!$A$7:$A$9,0)))*INDEX('26_STANDARD_COST'!$C$7:$C$9,MATCH(A25,'26_STANDARD_COST'!$A$7:$A$9,0)) | L25: =D25+E25+K25 | M25: =ROUND(INDEX('26_STANDARD_COST'!$G$7:$G$9,MATCH(A25,'26_STANDARD_COST'!$A$7:$A$9,0))+L25-INDEX('27_ACTUAL_COST'!$G$7:$G$9,MATCH(A25,'27_ACTUAL_COST'!$A$7:$A$9,0)),2)
A27: Recon check = (Std total + Total var) - Act total -> deve ser 0,00 por construcao.

Sheet 29_CAPACITY
A1: CAPACITY
A2: Horas ociosas = praticas - usadas. Unused Capacity Cost = ociosas x R$/hora. Este custo fica VISIVEL, nao e rateado ao produto.
A4: Legenda: | B4: INPUT (editavel) | D4: FORMULA | F4: LINKED (de outra aba) | H4: CONTROL | J4: ALERT | L4: CHAVE/ID
A6: RESOURCE_ID | B6: Horas praticas (link) | C6: Horas usadas (link OF) | D6: Horas ociosas | E6: R$/hora (link) | F6: UNUSED CAPACITY COST R$
A7: RES-MIST1 | B7: =SUMIF('12_RESOURCES'!$A$7:$A$67,A7,'12_RESOURCES'!$F$7:$F$67) | C7: =SUMIF('17_PRODUCTION_OF'!$E$7:$E$47,A7,'17_PRODUCTION_OF'!$Q$7:$Q$47) | D7: =B7-C7 | E7: =IFERROR(INDEX('15_RESOURCE_RATES'!$D$7:$D$9,MATCH(A7,'15_RESOURCE_RATES'!$A$7:$A$9,0)),0) | F7: =D7*E7
A8: RES-MIST2 | B8: =SUMIF('12_RESOURCES'!$A$7:$A$67,A8,'12_RESOURCES'!$F$7:$F$67) | C8: =SUMIF('17_PRODUCTION_OF'!$E$7:$E$47,A8,'17_PRODUCTION_OF'!$Q$7:$Q$47) | D8: =B8-C8 | E8: =IFERROR(INDEX('15_RESOURCE_RATES'!$D$7:$D$9,MATCH(A8,'15_RESOURCE_RATES'!$A$7:$A$9,0)),0) | F8: =D8*E8
A10: Total unused capacity cost: | F10: =SUM(F7:F8)

Sheet 08_PURCHASES
A1: PURCHASES
A2: Base bruta de compras. Alimenta 09_LANDED_COST e PPV (preco real vs padrao).
A4: Legenda: | B4: INPUT (editavel) | D4: FORMULA | F4: LINKED (de outra aba) | H4: CONTROL | J4: ALERT | L4: CHAVE/ID
A6: PURCHASE_ID | B6: MATERIAL_ID | C6: SUPPLIER_ID | D6: Data | E6: NF | F6: Qtd | G6: Unid | H6: Preco bruto R$/un | I6: Desconto R$ | J6: Frete R$ | K6: ICMS destac. R$ | L6: PIS/COFINS R$ | M6: Fonte | N6: Responsavel | O6: Vigencia ini | P6: Vigencia fim | Q6: Atualizado em | R6: Comentario
A7: PC-001 | B7: M001 | C7: S001 | D7: 2026-03-02 | E7: 12345 | F7: 30 | G7: t | H7: 700 | I7: 600 | J7: 1350 | K7: 3780 | L7: 0
A8: PC-002 | B8: M002 | C8: S002 | D8: 2026-03-03 | E8: 12346 | F8: 60 | G8: t | H8: 55 | I8: 0 | J8: 1320 | K8: 594 | L8: 0
A10: ^ Linhas acima = dados DEMO (marcados). Abaixo: campos de entrada em branco para dados reais.

Sheet 12_RESOURCES
A1: RESOURCES
A2: Base do Resource Cost Model e da capacidade pratica.
A4: Legenda: | B4: INPUT (editavel) | D4: FORMULA | F4: LINKED (de outra aba) | H4: CONTROL | J4: ALERT | L4: CHAVE/ID
A6: RESOURCE_ID | B6: Descricao | C6: COST_CENTER_ID | D6: Cap. nominal (t/h) | E6: Cap. pratica (t/h) | F6: Horas disp./mes | G6: Depreciacao R$/mes | H6: Manut. fixa R$/mes | I6: Outros fixos R$/mes | J6: Fonte | K6: Responsavel | L6: Vigencia ini | M6: Vigencia fim | N6: Atualizado em | O6: Comentario
A7: RES-MIST1 | B7: Misturador industrial 1 | C7: CC-PROD | D7: 8 | E7: 6.5 | F7: 360 | G7: 8000 | H7: 3000 | I7: 2000
A8: RES-MIST2 | B8: Misturador industrial 2 | C8: CC-PROD | D8: 6 | E8: 5 | F8: 360 | G8: 6000 | H8: 2500 | I8: 1500
A10: ^ Linhas acima = dados DEMO (marcados). Abaixo: campos de entrada em branco para dados reais.

Sheet 13_COST_CENTERS
A1: COST CENTERS
A2: Estrutura de acumulacao. Reprocesso tem centro proprio (nao contamina equipe principal).
A4: Legenda: | B4: INPUT (editavel) | D4: FORMULA | F4: LINKED (de outra aba) | H4: CONTROL | J4: ALERT | L4: CHAVE/ID
A6: COST_CENTER_ID | B6: Descricao | C6: Tipo | D6: Responsavel | E6: Custo fixo mes R$ | F6: Fonte | G6: Responsavel | H6: Vigencia ini | I6: Vigencia fim | J6: Atualizado em | K6: Comentario
A7: CC-PROD | B7: Producao principal | C7: Produtivo | D7: Sup. Producao | E7: 30000
A8: CC-REPRO | B8: Reprocesso | C8: Produtivo (separado) | D8: Sup. Producao | E8: 4000
A9: CC-LAB | B9: Laboratorio/Qualidade | C9: Apoio | D9: Qualidade | E9: 6000
A10: CC-MANUT | B10: Manutencao | C10: Apoio | D10: Manutencao | E10: 8000
A12: ^ Linhas acima = dados DEMO (marcados). Abaixo: campos de entrada em branco para dados reais.

Sheet 14_ROUTINGS
A1: ROUTINGS
A2: Etapas: dosagem, mistura, transferencia, ensacamento, paletizacao, lab, movim., armazenag. Alimenta Time-Driven ABC (taxa x tempo consumido).
A4: Legenda: | B4: INPUT (editavel) | D4: FORMULA | F4: LINKED (de outra aba) | H4: CONTROL | J4: ALERT | L4: CHAVE/ID
A6: ROUTING_ID | B6: PRODUCT_ID | C6: Seq | D6: Etapa | E6: RESOURCE_ID | F6: Tempo padrao (h/t) | G6: Cap (t/h)
A7: RT-EXT | B7: P001 | C7: 1 | D7: Dosagem | E7: RES-MIST1 | F7: 0.06 | G7: 8
A8: RT-EXT | B8: P001 | C8: 2 | D8: Mistura | E8: RES-MIST1 | F8: 0.1 | G8: 6.5
A9: RT-EXT | B9: P001 | C9: 3 | D9: Ensacamento | E9: RES-MIST1 | F9: 0.05 | G9: 8
A10: RT-ARG | B10: P002 | C10: 1 | D10: Mistura | E10: RES-MIST1 | F10: 0.12 | G10: 6.5
A11: RT-REJ | B11: P003 | C11: 1 | D11: Mistura | E11: RES-MIST2 | F11: 0.16 | G11: 5
A13: ^ Linhas acima = dados DEMO (marcados). Abaixo: campos de entrada em branco para dados reais.

Sheet 19_LOSSES
A1: LOSSES
A2: Mass balance: entrada = bom + perda normal + perda anormal + reproc + WIP + nao explicado. Diferenca nao explicada (UNACCOUNTED) nunca e absorvida automaticamente.
A4: Legenda: | B4: INPUT (editavel) | D4: FORMULA | F4: LINKED (de outra aba) | H4: CONTROL | J4: ALERT | L4: CHAVE/ID
A6: OF_ID | B6: PRODUCT_ID | C6: Entrada MP (t) | D6: Bom (t) | E6: Perda normal (t) | F6: Perda anormal (t) | G6: Reproc (t) | H6: WIP (t) | I6: Nao explicado (t)
A7: OF-2603-01 | B7: P001 | C7: 402 | D7: 400 | E7: 2 | F7: 0 | G7: 0 | H7: 0 | I7: =C7-D7-E7-F7-G7-H7
A8: OF-2603-02 | B8: P002 | C8: 251 | D8: 250 | E8: 1 | F8: 0 | G8: 0 | H8: 0 | I8: =C8-D8-E8-F8-G8-H8
A9: OF-2603-03 | B9: P003 | C9: 121.5 | D9: 120 | E9: 1 | F9: 0 | G9: 0.5 | H9: 0 | I9: =C9-D9-E9-F9-G9-H9
A11: ^ Linhas acima = dados DEMO (marcados). Abaixo: campos de entrada em branco para dados reais.

Sheet 20_REPROCESS
A1: REPROCESS
A2: Excluir reproc dos indicadores da equipe principal; NAO excluir seu custo economico. Net Reprocess = custo perdido + recuperacao - valor recuperado.
A4: Legenda: | B4: INPUT (editavel) | D4: FORMULA | F4: LINKED (de outra aba) | H4: CONTROL | J4: ALERT | L4: CHAVE/ID
A6: REPRO_ID | B6: OF_ID origem | C6: PRODUCT_ID | D6: Qtd (t) | E6: Custo original perdido R$ | F6: Custo recuperacao R$ | G6: Valor recuperado R$ | H6: NET reprocess R$
A7: RP-001 | B7: OF-2603-03 | C7: P003 | D7: 0.5 | E7: 150 | F7: 60 | G7: 120 | H7: =E7+F7-G7
A9: ^ Linhas acima = dados DEMO (marcados). Abaixo: campos de entrada em branco para dados reais.

Sheet 21_ENERGY
A1: ENERGY
A2: Energy Price Variance e Energy Usage Variance. kWh/t por OF quando disponivel.
A4: Legenda: | B4: INPUT (editavel) | D4: FORMULA | F4: LINKED (de outra aba) | H4: CONTROL | J4: ALERT | L4: CHAVE/ID
A6: PERIOD | B6: RESOURCE_ID | C6: kWh consumidos | D6: Tarifa R$/kWh | E6: Demanda R$ | F6: Producao t | G6: kWh/t | H6: Custo energia R$
A7: 2026-03 | B7: RES-MIST1 | C7: 9000 | D7: 0.72 | E7: 1500 | F7: 650 | G7: =IFERROR(C7/F7,0) | H7: =C7*D7+E7
A9: ^ Linhas acima = dados DEMO (marcados). Abaixo: campos de entrada em branco para dados reais.

Sheet 22_LABOR
A1: LABOR
A2: Separar hora normal, extra, setup, espera, reprocesso, absenteismo. Labor Efficiency Variance.
A4: Legenda: | B4: INPUT (editavel) | D4: FORMULA | F4: LINKED (de outra aba) | H4: CONTROL | J4: ALERT | L4: CHAVE/ID
A6: PERIOD | B6: COST_CENTER_ID | C6: Horas normais | D6: Horas extras | E6: Taxa normal R$/h | F6: Taxa extra R$/h | G6: Horas padrao | H6: Custo MO R$
A7: 2026-03 | B7: CC-PROD | C7: 480 | D7: 40 | E7: 22 | F7: 33 | G7: 470 | H7: =C7*E7+D7*F7
A9: ^ Linhas acima = dados DEMO (marcados). Abaixo: campos de entrada em branco para dados reais.

Sheet 23_MAINTENANCE
A1: MAINTENANCE
A2: Maintenance Cost/Running Hour e Breakdown Economic Cost (inclui perda de producao).
A4: Legenda: | B4: INPUT (editavel) | D4: FORMULA | F4: LINKED (de outra aba) | H4: CONTROL | J4: ALERT | L4: CHAVE/ID
A6: PERIOD | B6: RESOURCE_ID | C6: Tipo | D6: Pecas R$ | E6: Servicos R$ | F6: Horas parada | G6: Perda producao R$ | H6: Custo total R$
A7: 2026-03 | B7: RES-MIST1 | C7: Corretiva | D7: 800 | E7: 400 | F7: 3 | G7: 900 | H7: =D7+E7+G7
A9: ^ Linhas acima = dados DEMO (marcados). Abaixo: campos de entrada em branco para dados reais.

Sheet 24_QUALITY
A1: QUALITY
A2: Prevention, Appraisal, Internal Failure, External Failure. Alimenta 11_COPQ / dashboards.
A4: Legenda: | B4: INPUT (editavel) | D4: FORMULA | F4: LINKED (de outra aba) | H4: CONTROL | J4: ALERT | L4: CHAVE/ID
A6: PERIOD | B6: PRODUCT_ID | C6: Classe | D6: Categoria | E6: Valor R$ | F6: Causa | G6: Responsavel area
A7: 2026-03 | B7: P003 | C7: Internal Failure | D7: Reprocesso | E7: 90 | F7: Ajuste cor | G7: Producao
A8: 2026-03 | B8: P001 | C8: Appraisal | D8: Ensaio lab | E8: 200 | F8: Controle rotina | G8: Qualidade
A10: ^ Linhas acima = dados DEMO (marcados). Abaixo: campos de entrada em branco para dados reais.

Sheet 25_INVENTORY
A1: INVENTORY
