Workbook

Sheet Resumo
A1: SKAL ENGENHARIA - COMPRAS / ENTRADAS - JANEIRO 2026
A2: Extração contábil e fiscal completa do PDF, com controle de duplicidades e trilha de revisão.
A4: Arquivo fonte | B4: NOTAS FISCAIS DE COMPRA JANEIRO 2026.pdf
A5: Páginas analisadas | B5: 303
A6: Período | B6: Janeiro/2026 (inclui documentos de competência/emissão anterior presentes no arquivo)
A7: Critério | B7: Somente linhas com Soma_Contabil = Sim entram no Total Confirmado. Duplicados exatos são excluídos; possíveis duplicidades ficam em Revisar.
A10: Total confirmado | B10: =SUMIFS(Documentos!$Q:$Q,Documentos!$AO:$AO,"Sim")
A11: Valor em revisão | B11: =SUMIFS(Documentos!$Q:$Q,Documentos!$AO:$AO,"Revisar")
A12: Valor excluído - duplicados exatos | B12: =SUMIFS(Documentos!$Q:$Q,Documentos!$AQ:$AQ,"Duplicado exato")
A13: Qtd. documentos/páginas confirmados | B13: =COUNTIF(Documentos!$AO:$AO,"Sim")
A14: Qtd. em revisão | B14: =COUNTIF(Documentos!$AO:$AO,"Revisar")
A15: Qtd. duplicados exatos | B15: =COUNTIF(Documentos!$AQ:$AQ,"Duplicado exato")
A18: Categoria | B18: Total confirmado | C18: Em revisão
A19: Produtos | B19: =SUMIFS(Documentos!$Q:$Q,Documentos!$N:$N,A19,Documentos!$AO:$AO,"Sim") | C19: =SUMIFS(Documentos!$Q:$Q,Documentos!$N:$N,A19,Documentos!$AO:$AO,"Revisar")
A20: Serviços | B20: =SUMIFS(Documentos!$Q:$Q,Documentos!$N:$N,A20,Documentos!$AO:$AO,"Sim") | C20: =SUMIFS(Documentos!$Q:$Q,Documentos!$N:$N,A20,Documentos!$AO:$AO,"Revisar")
A21: Fretes | B21: =SUMIFS(Documentos!$Q:$Q,Documentos!$N:$N,A21,Documentos!$AO:$AO,"Sim") | C21: =SUMIFS(Documentos!$Q:$Q,Documentos!$N:$N,A21,Documentos!$AO:$AO,"Revisar")
A22: Energia | B22: =SUMIFS(Documentos!$Q:$Q,Documentos!$N:$N,A22,Documentos!$AO:$AO,"Sim") | C22: =SUMIFS(Documentos!$Q:$Q,Documentos!$N:$N,A22,Documentos!$AO:$AO,"Revisar")
A23: Telecomunicações | B23: =SUMIFS(Documentos!$Q:$Q,Documentos!$N:$N,A23,Documentos!$AO:$AO,"Sim") | C23: =SUMIFS(Documentos!$Q:$Q,Documentos!$N:$N,A23,Documentos!$AO:$AO,"Revisar")
A24: Apoio/Outros | B24: =SUMIFS(Documentos!$Q:$Q,Documentos!$N:$N,A24,Documentos!$AO:$AO,"Sim") | C24: =SUMIFS(Documentos!$Q:$Q,Documentos!$N:$N,A24,Documentos!$AO:$AO,"Revisar")
A27: Observações de qualidade
A28: 1. O PDF é escaneado; campos OCR de baixa/média confiança permanecem na planilha, mas são sinalizados para revisão.
A29: 2. Duplicidades exatas encontradas: p.13=p.12; p.134=p.82; p.153=p.64; p.156=p.154; p.165=p.131; p.166=p.132; p.199=p.145; p.200=p.70.
A30: 3. NFS-e Juvencio p.69 e p.70 têm mesmo valor e mesma descrição de comissão, mas números/datas distintos; foram tratadas como possível duplicidade comercial e não somadas até confirmação.
A31: 4. Boletos, MDF-e, DAR/GNRE, separadores e documentos meramente de apoio não são somados como nova compra.
A32: 5. A aba OCR_Raw preserva o texto extraído de todas as 303 páginas para auditoria e busca.

Sheet Documentos
A1: Doc_ID | B1: Pagina | C1: Tipo | D1: Modelo | E1: Numero | F1: Serie | G1: Data_Emissao | H1: Vencimento | I1: Chave_Acesso | J1: Emitente | K1: CNPJ_Emitente | L1: CNPJ_Destinatario | M1: Unidade_SKAL | N1: Categoria | O1: Subcategoria | P1: Descricao | Q1: Valor_Documento | R1: Valor_Produtos | S1: Valor_Servicos | T1: Valor_Frete | U1: BC_ICMS | V1: Aliq_ICMS | W1: ICMS | X1: BC_ICMS_ST | Y1: ICMS_ST | Z1: IPI | AA1: PIS | AB1: COFINS | AC1: BC_ISS | AD1: Aliq_ISS | AE1: ISS | AF1: IRRF_Retido | AG1: CSLL_Retida | AH1: PIS_Retido | AI1: COFINS_Retido | AJ1: INSS_Retido | AK1: Valor_Liquido | AL1: Valor_Mercadoria_CTe | AM1: Confianca_OCR | AN1: Flag_Fiscal | AO1: Soma_Contabil | AP1: Duplicado_de | AQ1: Status_Duplicidade | AR1: Observacoes | AS1: Fonte
A2: JAN26-P001 | B2: 1 | C2: Energia/NF3e | D2: 66 | E2: 67912850 | F2: 000 | G2: 46053 | H2: 46059 | I2: 22260106840748000189660000679128501095737069 | J2: EQUATORIAL PIAUI DISTRIBUIDORA DE ENERGIA S.A. | K2: 06.840.748/0001-89 | L2: 23.655.038/0002-89 | M2: SKAL /0002 | N2: Energia | O2: Energia eletrica - unidade industrial | Q2: 23789.49 | U2: 21764.76 | V2: 0.225 | W2: 4892.56 | AA2: 125.55 | AB2: 580.23 | AM2: Alta | AO2: Sim | AS2: NOTAS FISCAIS DE COMPRA JANEIRO 2026.pdf - p. 1
A3: JAN26-P002 | B3: 2 | C3: Outros/Documento | J3: Greta ica force pogo, Para mexet nas insialarben, | N3: Apoio | O3: Documento de apoio | AM3: Baixa | AO3: Não | AQ3: Continuacao do documento da pagina 1 - nao somar separadamente | AS3: NOTAS FISCAIS DE COMPRA JANEIRO 2026.pdf - p. 2
A4: JAN26-P003 | B4: 3 | C4: Energia/NF3e | D4: 66 | E4: 67620505 | F4: 000 | G4: 46048 | H4: 46055 | I4: 22260106840748000189660000676205052066826930 | J4: EQUATORIAL PIAUI DISTRIBUIDORA DE ENERGIA S.A. | K4: 06.840.748/0001-89 | L4: 23.655.038/0001-06 | M4: SKAL /0001 | N4: Energia | O4: Energia eletrica - unidade administrativa | Q4: 29.6 | U4: 0 | W4: 0 | AA4: 0.2 | AB4: 0.92 | AM4: Alta | AO4: Sim | AS4: NOTAS FISCAIS DE COMPRA JANEIRO 2026.pdf - p. 3
A5: JAN26-P004 | B5: 4 | C5: Energia/NF3e | D5: 66 | E5: 67003437 | F5: 000 | G5: 46038 | H5: 46045 | I5: 22260106840748000189660000670034372083880016 | J5: EQUATORIAL PIAUI DISTRIBUIDORA DE ENERGIA S.A. | K5: 06.840.748/0001-89 | L5: 23.655.038/0001-06 | M5: SKAL /0001 | N5: Energia | O5: Energia eletrica - unidade administrativa | Q5: 29.78 | U5: 0 | W5: 0 | AA5: 0.2 | AB5: 0.93 | AM5: Alta | AO5: Sim | AS5: NOTAS FISCAIS DE COMPRA JANEIRO 2026.pdf - p. 4
A6: JAN26-P005 | B6: 5 | C6: Energia/NF3e | D6: 66 | E6: 67888805 | F6: 000 | G6: 46051 | H6: 46058 | I6: 22260106840748000189660000678888051049698360 | J6: EQUATORIAL PIAUI DISTRIBUIDORA DE ENERGIA S.A. | K6: 06.840.748/0002-69 | L6: 23.655.038/0002-89 | M6: SKAL /0002 | N6: Energia | O6: Energia eletrica - unidade administrativa | Q6: 843.08 | U6: 773.85 | V6: 0.225 | W6: 174.11 | AA6: 4.06 | AB6: 18.78 | AM6: Alta | AO6: Sim | AS6: NOTAS FISCAIS DE COMPRA JANEIRO 2026.pdf - p. 5
A7: JAN26-P006 | B7: 6 | C7: Separador/Anotacao | J7: PERIODO MES DE | N7: Apoio | O7: Documento de apoio | AM7: Baixa | AO7: Não | AS7: NOTAS FISCAIS DE COMPRA JANEIRO 2026.pdf - p. 6
A8: JAN26-P007 | B8: 7 | C8: NF-e | G8: 45687 | J8: ‘wrwwenfefazenda.gov-briportal ou no site da Sefaz Autorizadora | N8: Produtos | O8: Outros produtos | P8: vet | ao | ‘con op. | escuK0 Do FROTUTES /SERVICOS | worst] esr | cro |unaol quampane Jy.tarriwo| vitorat | nesenes | v.seus | SR | 000 | 65990] Goo | 3556 | UN] | Tog | Tai635] | Ta1635) | 060) | 0,00] | 0300) | 2.0] | jorse79 | ISECAODAJANELA | wrt, | AM8: Baixa | AN8: Revisar documento | AO8: Revisar | AS8: NOTAS FISCAIS DE COMPRA JANEIRO 2026.pdf - p. 7
A9: JAN26-P008 | B9: 8 | C9: NF-e | J9: FORNECEDORA CAMINHOES COMERCIO SERVIC | N9: Produtos | O9: Outros produtos | AM9: Baixa | AN9: Revisar documento | AO9: Revisar | AS9: NOTAS FISCAIS DE COMPRA JANEIRO 2026.pdf - p. 8
A10: JAN26-P009 | B10: 9 | C10: Boleto/Financeiro | J10: FORNECEDORA CAMINHOES COMERCIO E SERVIGOS LTDA, CNPJ:19.377.865/0006-04 | K10: 19.377.865/0006-04 | L10: 23.655.038/0002-89 | M10: SKAL /0002 | N10: Apoio | O10: Documento de apoio | AM10: Media | AO10: Não | AS10: NOTAS FISCAIS DE COMPRA JANEIRO 2026.pdf - p. 9
A11: JAN26-P010 | B11: 10 | C11: Boleto/Financeiro | J11: FORNECEDORA CAMINHOES COMERCIO & SERVICOS LTDA, CNPJ:19:377.805/0006-04 | N11: Apoio | O11: Documento de apoio | AM11: Baixa | AO11: Não | AS11: NOTAS FISCAIS DE COMPRA JANEIRO 2026.pdf - p. 10
A12: JAN26-P011 | B12: 11 | C12: Boleto/Financeiro | J12: FORNECEDORA CAMINHOES COMERCIO E SERVICOS LTDA, CNPJ:19.377.805/0006-04 | L12: 23.655.038/0002-89 | M12: SKAL /0002 | N12: Apoio | O12: Documento de apoio | AM12: Baixa | AO12: Não | AS12: NOTAS FISCAIS DE COMPRA JANEIRO 2026.pdf - p. 11
A13: JAN26-P012 | B13: 12 | C13: NFS-e | E13: 863 | F13: U | G13: 46022 | J13: GESTAO - INOVACAO EMPRESARIAL LTDA | K13: 20.504.019/0001-82 | L13: 23.655.038/0002-89 | M13: SKAL /0002 | N13: Servicos | O13: Consultoria/assessoria | P13: SERVICO DE ACOMPANHAMENTO DE PROCESSOS ADMINISTRATIVOS, REFERENTE AO MES DE NOVEMBRO DE 2025 | Q13: 759 | S13: 759 | AM13: Alta | AO13: Sim | AS13: NOTAS FISCAIS DE COMPRA JANEIRO 2026.pdf - p. 12
A14: JAN26-P013 | B14: 13 | C14: NFS-e | E14: 863 | F14: U | G14: 46022 | J14: GESTAO - INOVACAO EMPRESARIAL LTDA | K14: 20.504.019/0001-82 | L14: 23.655.038/0002-89 | M14: SKAL /0002 | N14: Servicos | O14: Consultoria/assessoria | P14: SERVICO DE ACOMPANHAMENTO DE PROCESSOS ADMINISTRATIVOS, REFERENTE AO MES DE NOVEMBRO DE 2025 | Q14: 759 | S14: 759 | AM14: Alta | AO14: Não | AP14: P12 | AQ14: Duplicado exato | AR14: Página repetida do mesmo documento fiscal; excluída da soma para evitar dupla contabilização. | AS14: NOTAS FISCAIS DE COMPRA JANEIRO 2026.pdf - p. 13
A15: JAN26-P014 | B15: 14 | C15: NFCom | D15: 62 | E15: 303 | F15: 001 | G15: 46034 | H15: 46042 | I15: 22260109590480000162620010000003031062963074 | J15: TELEVISAO PIONEIRA LTDA | K15: 09.590.480/0001-62 | L15: 23.655.038/0002-89 | M15: SKAL /0002 | N15: Servicos | O15: Publicidade/patrocinio em comunicacao | P15: VEICULACAO VT 30, PATROCINIO - CIDADE VERDE ESPORTE. PERIODO: JANEIRO A DEZEMBRO DE 2026. PRODUTO: KALFIX - CIMENTO APODI. PARCELA 01/12. | Q15: 10000 | U15: 0 | W15: 0 | AA15: 65 | AB15: 300 | AM15: Alta | AO15: Sim | AS15: NOTAS FISCAIS DE COMPRA JANEIRO 2026.pdf - p. 14
A16: JAN26-P015 | B16: 15 | C16: Outros/Documento | J16: MOS DE F & | INDUSTRIA E COMERCIO DE PRODUTOS DE LIMPEZA LTDA | N16: Apoio | O16: Documento de apoio | AM16: Baixa | AO16: Não | AS16: NOTAS FISCAIS DE COMPRA JANEIRO 2026.pdf - p. 15
A17: JAN26-P016 | B17: 16 | C17: NF-e | G17: 46050 | J17: | www.nfe.fazenda.gov.br/portal ou no site da Sefaz Autorizadora | K17: 31.838.128/0025-20 | N17: Produtos | O17: Outros produtos | AM17: Media | AN17: Revisar documento | AO17: Revisar | AS17: NOTAS FISCAIS DE COMPRA JANEIRO 2026.pdf - p. 16
A18: JAN26-P017 | B18: 17 | C18: CT-e | D18: 57 | E18: 446 | F18: 1 | G18: 46050 | I18: 23260142709787000377570010000004461000000000 | J18: F G INTELIGENCIA EM LOGISTICA LTDA | K18: 42.709.787/0003-77 | L18: 23.655.038/0002-89 | M18: SKAL /0002 | N18: Fretes | O18: Frete de insumo - cimento | P18: Frete rodoviário de aquisição de cimento - remetente Companhia Industrial de Cimento Apodi. | Q18: 11702.5 | T18: 11702.5 | U18: 11702.5 | V18: 0.12 | W18: 1404.3 | AL18: 18686.25 | AM18: Alta | AO18: Sim | AS18: NOTAS FISCAIS DE COMPRA JANEIRO 2026.pdf - p. 17
A19: JAN26-P018 | B19: 18 | C19: CT-e | D19: 57 | E19: 445 | F19: 1 | G19: 46049 | I19: 23260142709787000377570010000004451000000002 | J19: F G INTELIGENCIA EM LOGISTICA LTDA | K19: 42.709.787/0003-77 | L19: 23.655.038/0002-89 | M19: SKAL /0002 | N19: Fretes | O19: Frete de insumo - cimento | P19: Frete rodoviário de aquisição de cimento - remetente Companhia Industrial de Cimento Apodi. | Q19: 11838.9 | S19: 1938.9 | T19: 11838.9 | U19: 11838.9 | V19: 0.12 | W19: 1420.67 | AL19: 18904.05 | AM19: Alta | AO19: Sim | AS19: NOTAS FISCAIS DE COMPRA JANEIRO 2026.pdf - p. 18
A20: JAN26-P019 | B20: 19 | C20: CT-e | D20: 57 | E20: 443 | F20: 1 | G20: 46046 | I20: 23260142709787000377570010000004431000000008 | J20: F G INTELIGENCIA EM LOGISTICA LTDA | K20: 42.709.787/0003-77 | L20: 23.655.038/0002-89 | M20: SKAL /0002 | N20: Fretes | O20: Frete de insumo - cimento | P20: Frete rodoviário de aquisição de cimento - remetente Companhia Industrial de Cimento Apodi. | Q20: 11789.3 | S20: 1.79 | T20: 11789.3 | U20: 11789.3 | V20: 0.12 | W20: 1414.72 | AL20: 18824.85 | AM20: Alta | AO20: Sim | AS20: NOTAS FISCAIS DE COMPRA JANEIRO 2026.pdf - p. 19
A21: JAN26-P020 | B21: 20 | C21: NF-e | D21: 55 | E21: 42508 | F21: 1 | G21: 46051 | I21: 22260129190494000368550010000425081902488401 | J21: www nfefazenda,gov.briportal ou no site da Sefiv Autorizadora | K21: 29.190.494/0003-68 | L21: 23.655.038/0002-89 | M21: SKAL /0002 | N21: Produtos | O21: Outros produtos | AM21: Alta | AN21: Revisar documento | AO21: Revisar | AS21: NOTAS FISCAIS DE COMPRA JANEIRO 2026.pdf - p. 20
A22: JAN26-P021 | B22: 21 | C22: NF-e | G22: 46051 | J22: www. nfe.fazenda,gov.br/portal ou no site da Sefaz Autorizadora | K22: 29.190.494/0003-68 | N22: Produtos | O22: Materia-prima - cimento | AM22: Media | AN22: Revisar documento | AO22: Revisar | AS22: NOTAS FISCAIS DE COMPRA JANEIRO 2026.pdf - p. 21
A23: JAN26-P022 | B23: 22 | C23: NF-e | E23: 537098 | G23: 46050 | J23: COMPANHIA INDUSTRIAL DE CIMENTO APODI | K23: 10.260.249/0003-51 | L23: 23.655.038/0002-89 | M23: SKAL /0002 | N23: Produtos | O23: Cimento | P23: Cimento Portland / produção do estabelecimento - dados fiscais conforme DANFE. | Q23: 18686.25 | R23: 18686.25 | U23: 18686.25 | V23: 0.12 | W23: 2242.35 | AM23: Media | AO23: Sim | AS23: NOTAS FISCAIS DE COMPRA JANEIRO 2026.pdf - p. 22
A24: JAN26-P023 | B24: 23 | C24: NF-e | E24: 536966 | G24: 46049 | J24: COMPANHIA INDUSTRIAL DE CIMENTO APODI | K24: 10.260.249/0003-51 | L24: 23.655.038/0002-89 | M24: SKAL /0002 | N24: Produtos | O24: Cimento | P24: Cimento Portland / produção do estabelecimento - dados fiscais conforme DANFE. | Q24: 18904.05 | R24: 18904.05 | U24: 18904.05 | V24: 0.12 | W24: 2268.49 | AM24: Media | AO24: Sim | AS24: NOTAS FISCAIS DE COMPRA JANEIRO 2026.pdf - p. 23
A25: JAN26-P024 | B25: 24 | C25: NF-e | E25: 536748 | G25: 46046 | J25: COMPANHIA INDUSTRIAL DE CIMENTO APODI | K25: 10.260.249/0003-51 | L25: 23.655.038/0002-89 | M25: SKAL /0002 | N25: Produtos | O25: Cimento | P25: Cimento Portland / produção do estabelecimento - dados fiscais conforme DANFE. | Q25: 18824.85 | R25: 18824.85 | U25: 18824.85 | V25: 0.12 | W25: 2258.98 | AM25: Media | AO25: Sim | AS25: NOTAS FISCAIS DE COMPRA JANEIRO 2026.pdf - p. 24
A26: JAN26-P025 | B26: 25 | C26: CT-e | J26: TRANS VNC TRANSPORTES EIRELI | N26: Fretes | O26: Frete rodoviário | Q26: 703 | T26: 703 | U26: 410.1 | V26: 0.12 | W26: 49.21 | AL26: 9135 | AM26: Baixa | AN26: Revisar documento | AO26: Revisar | AR26: CT-e TRANS VMC: valor lido visualmente; confirmar chave/total antes da contabilização. | AS26: NOTAS FISCAIS DE COMPRA JANEIRO 2026.pdf - p. 25
A27: JAN26-P026 | B27: 26 | C27: NF-e | G27: 46034 | J27: TE5TOCOLO DE AUTORLZNGRODEUSO | K27: 04.949.601/0001-04 | L27: 23.655.038/0002-89 | M27: SKAL /0002 | N27: Produtos | O27: Outros produtos | P27: oo | esciugdo Do PRODUTOSERVIGO | Naw | vaton | moras | Walon ToT | 400, | cs | =| | woos | AAILCELESTE SG | Taos | sea | ae | ro | Taal | R27: 9135 | T27: 0 | AM27: Media | AN27: Revisar documento | AO27: Revisar | AS27: NOTAS FISCAIS DE COMPRA JANEIRO 2026.pdf - p. 26
A28: JAN26-P027 | B28: 27 | C28: Separador/Anotacao | N28: Apoio | O28: Documento de apoio | AM28: Baixa | AO28: Não | AS28: NOTAS FISCAIS DE COMPRA JANEIRO 2026.pdf - p. 27
A29: JAN26-P028 | B29: 28 | C29: NFS-e | G29: 46055 | J29: TERRA NOVA (LOT. Meco 16459, SAO SEBASTIAO. | L29: 23.655.038/0002-89 | M29: SKAL /0002 | N29: Servicos | O29: Outros servicos | Q29: 7.5 | AA29: 0 | AB29: 0 | AM29: Media | AO29: Sim | AS29: NOTAS FISCAIS DE COMPRA JANEIRO 2026.pdf - p. 28
A30: JAN26-P029 | B30: 29 | C30: NFS-e | G30: 46055 | J30: RIGARDO RODRIGUES DE SOUSA 90931442370 | K30: 40.439.061/0001-74 | N30: Servicos | O30: Outros servicos | AA30: 0 | AB30: 0 | AM30: Media | AN30: Revisar documento | AO30: Revisar | AS30: NOTAS FISCAIS DE COMPRA JANEIRO 2026.pdf - p. 29
A31: JAN26-P030 | B31: 30 | C31: NFS-e | G31: 46048 | J31: JESUINO@APOIOCONTABILP.COM | L31: 23.655.038/0002-89 | M31: SKAL /0002 | N31: Servicos | O31: Outros servicos | Q31: 4198 | AB31: 0 | AE31: 4198 | AM31: Media | AN31: ISS OCR suspeito | AO31: Sim | AR31: ALERTA: ISS extraído por OCR parece incompatível com o valor do documento; conferir original. | AS31: NOTAS FISCAIS DE COMPRA JANEIRO 2026.pdf - p. 30
A32: JAN26-P031 | B32: 31 | C32: NFS-e | E32: 5 | F32: 12 | G32: 45996 | J32: - REPRESENTANTES COMERCIAIS E AGENTES DO COMERGIO DE MADEIRA, MATERIAL DE CONSTRUCAO E FERRAGENS, | N32: Servicos | O32: Representacao/comissoes | Q32: 797.56 | AC32: 791.96 | AM32: Media | AO32: Sim | AS32: NOTAS FISCAIS DE COMPRA JANEIRO 2026.pdf - p. 31
A33: JAN26-P032 | B33: 32 | C33: NF-e | G33: 46036 | J33: Dest Skin NGENHARIA INDUSTRIA E COMERCIO LTDA AVENIDA SAOTRANCISCO, 100 -PAROUE JUKEMA » TERFSINA 1 | N33: Produtos | O33: Outros produtos | P33: 0180 | on) | vee | ry | maree | ae | voere | sesoncAaporecUTosemHCo | ven | or | ‘ec | mo | ouawroace | ven | Es | ane. | cS | AM33: Baixa | AN33: Revisar documento | AO33: Revisar | AS33: NOTAS FISCAIS DE COMPRA JANEIRO 2026.pdf - p. 32
A34: JAN26-P033 | B34: 33 | C34: DAR/GNRE | G34: 46037 | J34: [AV SAO FRANCISCO, 4900, | N34: Apoio | O34: Documento de apoio | AM34: Baixa | AO34: Não | AS34: NOTAS FISCAIS DE COMPRA JANEIRO 2026.pdf - p. 33
A35: JAN26-P034 | B35: 34 | C35: DAR/GNRE | G35: 46036 | J35: GERENCIA DE FISCALIZAGAO DE MERCADORIA EM TRANSITO | N35: Apoio | O35: Documento de apoio | AM35: Baixa | AO35: Não | AS35: NOTAS FISCAIS DE COMPRA JANEIRO 2026.pdf - p. 34
A36: JAN26-P035 | B36: 35 | C36: NFS-e | E36: 0 | F36: 01 | J36: CONSULTING AND INFORMATION SERVICES LTOA | L36: 23.655.038/0002-89 | M36: SKAL /0002 | N36: Servicos | O36: Consultoria/assessoria | Q36: 9689.93 | AA36: 0 | AC36: 9.68 | AE36: 9689.93 | AM36: Media | AN36: ISS OCR suspeito | AO36: Sim | AR36: ALERTA: ISS extraído por OCR parece incompatível com o valor do documento; conferir original. | AS36: NOTAS FISCAIS DE COMPRA JANEIRO 2026.pdf - p. 35
A37: JAN26-P036 | B37: 36 | C37: NF-e | E37: 222 | G37: 46036 | J37: \CPNGENIARIA INDUSTRIA F COMERCKO LTDA AVENIDA SAO FRANCISCO, 4000- PARQUE JUREMA - TERESINA = | K37: 46.091.289/0001-00 | L37: 23.655.038/0002-89 | M37: SKAL /0002 | N37: Produtos | O37: Materia-prima mineral | P37: eae | cry | Tao | “aa | rod | cry | am | ae | oo | Descae40 9 HeOWT ERIE | Ebsss | rows | on | oo | ‘ae. ournase | owns | osseons | voi | AM37: Media | AN37: Revisar documento | AO37: Revisar | AS37: NOTAS FISCAIS DE COMPRA JANEIRO 2026.pdf - p. 36
A38: JAN26-P037 | B38: 37 | C38: DAR/GNRE | G38: 46037 | J38: LOCAIS DE PAGAMENTO ITAU, SANTANDER, BANCO DO BRASIL, CAIXA ECONOMICA FEDERAL, | L38: 23.655.038/0002-89 | M38: SKAL /0002 | N38: Apoio | O38: Documento de apoio | AM38: Baixa | AO38: Não | AS38: NOTAS FISCAIS DE COMPRA JANEIRO 2026.pdf - p. 37
A39: JAN26-P038 | B39: 38 | C39: DAR/GNRE | G39: 46036 | J39: GERENCIA DE FISCALIZACAO DE MERCADORIA EM TRANSITO | N39: Apoio | O39: Documento de apoio | AM39: Baixa | AO39: Não | AS39: NOTAS FISCAIS DE COMPRA JANEIRO 2026.pdf - p. 38
A40: JAN26-P039 | B40: 39 | C40: NFS-e | G40: 46016 | J40: AUTO SHOP RASTREAMENTO LTDA | K40: 24.625.077/0001-15 | N40: Servicos | O40: Outros servicos | Q40: 1198 | AM40: Media | AO40: Sim | AS40: NOTAS FISCAIS DE COMPRA JANEIRO 2026.pdf - p. 39
...

Sheet Itens_Produtos
A1: Doc_ID | B1: Pagina | C1: NF_e | D1: Data | E1: Fornecedor | F1: CNPJ | G1: Descricao_Produto_OCR | H1: NCM_SH | I1: CFOP | J1: Unidade | K1: Quantidade | L1: Valor_Unitario | M1: Valor_Produtos | N1: BC_ICMS | O1: ICMS | P1: ICMS_ST | Q1: IPI | R1: Soma_Contabil | S1: Confianca | T1: Fonte
A2: JAN26-P007 | B2: 7 | D2: 45687 | E2: ‘wrwwenfefazenda.gov-briportal ou no site da Sefaz Autorizadora | G2: vet | ‘con op. | escuK0 Do FROTUTES /SERVICOS | worst] esr | cro |unaol quampane Jy.tarriwo| vitorat | nesenes | v.seus | SR | 000 | 65990] Goo | 3556 | UN] | Tog | Tai635] | Ta1635) | 060) | 0,00] | 0300) | 2.0] | jorse79 | ISECAODAJANELA | R2: Revisar | S2: Baixa | T2: NOTAS FISCAIS DE COMPRA JANEIRO 2026.pdf - p. 7
A3: JAN26-P008 | B3: 8 | E3: FORNECEDORA CAMINHOES COMERCIO SERVIC | R3: Revisar | S3: Baixa | T3: NOTAS FISCAIS DE COMPRA JANEIRO 2026.pdf - p. 8
A4: JAN26-P016 | B4: 16 | D4: 46050 | E4: | www.nfe.fazenda.gov.br/portal ou no site da Sefaz Autorizadora | F4: 31.838.128/0025-20 | R4: Revisar | S4: Media | T4: NOTAS FISCAIS DE COMPRA JANEIRO 2026.pdf - p. 16
A5: JAN26-P020 | B5: 20 | C5: 42508 | D5: 46051 | E5: www nfefazenda,gov.briportal ou no site da Sefiv Autorizadora | F5: 29.190.494/0003-68 | R5: Revisar | S5: Alta | T5: NOTAS FISCAIS DE COMPRA JANEIRO 2026.pdf - p. 20
A6: JAN26-P021 | B6: 21 | D6: 46051 | E6: www. nfe.fazenda,gov.br/portal ou no site da Sefaz Autorizadora | F6: 29.190.494/0003-68 | G6: TENCIMENTO | VALOR | FATURA BUPLIC | R6: Revisar | S6: Media | T6: NOTAS FISCAIS DE COMPRA JANEIRO 2026.pdf - p. 21
A7: JAN26-P022 | B7: 22 | C7: 537098 | D7: 46050 | E7: COMPANHIA INDUSTRIAL DE CIMENTO APODI | F7: 10.260.249/0003-51 | G7: {MOS DE COMPANHIA INDUSTRIAL DE CIMENTO APODI_OS PRODUTOS CONSTANTES DA NOTA FISC | INDI | DA AO LADO | M7: 18686.25 | N7: 18686.25 | O7: 2242.35 | R7: Sim | S7: Media | T7: NOTAS FISCAIS DE COMPRA JANEIRO 2026.pdf - p. 22
A8: JAN26-P023 | B8: 23 | C8: 536966 | D8: 46049 | E8: COMPANHIA INDUSTRIAL DE CIMENTO APODI | F8: 10.260.249/0003-51 | G8: VENDA DE PRODUCAO DO ESTABELECIMENTO. | INSCR TST. SUBS. TBUTARIO | RPC | M8: 18904.05 | N8: 18904.05 | O8: 2268.49 | R8: Sim | S8: Media | T8: NOTAS FISCAIS DE COMPRA JANEIRO 2026.pdf - p. 23
A9: JAN26-P024 | B9: 24 | C9: 536748 | D9: 46046 | E9: COMPANHIA INDUSTRIAL DE CIMENTO APODI | F9: 10.260.249/0003-51 | G9: | COMPANHIA INDUSTRIAL DE CIMENTO APODE | pocumesro atin Da | Ropes SantwONe | M9: 18824.85 | N9: 18824.85 | O9: 2258.98 | R9: Sim | S9: Media | T9: NOTAS FISCAIS DE COMPRA JANEIRO 2026.pdf - p. 24
A10: JAN26-P026 | B10: 26 | D10: 46034 | E10: TE5TOCOLO DE AUTORLZNGRODEUSO | F10: 04.949.601/0001-04 | G10: esciugdo Do PRODUTOSERVIGO | Naw | vaton | moras | Walon ToT | 400, | woos | AAILCELESTE SG | Taos | sea | M10: 9135 | R10: Revisar | S10: Media | T10: NOTAS FISCAIS DE COMPRA JANEIRO 2026.pdf - p. 26
A11: JAN26-P032 | B11: 32 | D11: 46036 | E11: Dest Skin NGENHARIA INDUSTRIA E COMERCIO LTDA AVENIDA SAOTRANCISCO, 100 -PAROUE JUKEMA » TERFSINA 1 | G11: 0180 | on) | vee | maree | voere | sesoncAaporecUTosemHCo | ven | ‘ec | mo | ouawroace | ven | ane. | R11: Revisar | S11: Baixa | T11: NOTAS FISCAIS DE COMPRA JANEIRO 2026.pdf - p. 32
A12: JAN26-P036 | B12: 36 | C12: 222 | D12: 46036 | E12: \CPNGENIARIA INDUSTRIA F COMERCKO LTDA AVENIDA SAO FRANCISCO, 4000- PARQUE JUREMA - TERESINA = | F12: 46.091.289/0001-00 | G12: CAULIM MALIA 28 | bsuroa| am | aan | R12: Revisar | S12: Media | T12: NOTAS FISCAIS DE COMPRA JANEIRO 2026.pdf - p. 36
A13: JAN26-P041 | B13: 41 | C13: 536564 | D13: 46045 | E13: COMPANHIA INDUSTRIAL DE CIMENTO APODI | F13: 10.260.249/0003-51 | G13: It INDUSTRIAL De cIMENTO AroDI | Say | M13: 17790.3 | N13: 17790.3 | O13: 2134.84 | R13: Sim | S13: Alta | T13: NOTAS FISCAIS DE COMPRA JANEIRO 2026.pdf - p. 41
A14: JAN26-P042 | B14: 42 | C14: 536357 | D14: 46044 | E14: COMPANHIA INDUSTRIAL DE CIMENTO APODI | F14: 10.260.249/0003-51 | G14: INDUSTRIAL DE CIMENTO APODI | Sore | ons suces: | M14: 18607.05 | N14: 18607.05 | O14: 2232.85 | R14: Sim | S14: Media | T14: NOTAS FISCAIS DE COMPRA JANEIRO 2026.pdf - p. 42
A15: JAN26-P043 | B15: 43 | C15: 536302 | D15: 46043 | E15: COMPANHIA INDUSTRIAL DE CIMENTO APODI | F15: 10.260.249/0003-51 | G15: |coMPANHIA INDUSTRIAL DE CIMENTO AFODI | RGEC A | veh | M15: 18711 | N15: 18711 | O15: 2245.32 | R15: Sim | S15: Media | T15: NOTAS FISCAIS DE COMPRA JANEIRO 2026.pdf - p. 43
A16: JAN26-P044 | B16: 44 | C16: 536108 | D16: 46042 | E16: COMPANHIA INDUSTRIAL DE CIMENTO APODI | F16: 10.260.249/0003-51 | G16: (COMPANIIA INDUSTRIAL DE CIMENTO APODE | RONEN | poceamsto wuttste oe | M16: 18814.95 | N16: 18814.95 | O16: 2257.79 | R16: Sim | S16: Media | T16: NOTAS FISCAIS DE COMPRA JANEIRO 2026.pdf - p. 44
A17: JAN26-P045 | B17: 45 | C17: 535954 | D17: 46041 | E17: COMPANHIA INDUSTRIAL DE CIMENTO APODI | F17: 10.260.249/0003-51 | G17: compan 1NAUSTRE:L. DE CIMENTO APODL | SORE AGEL | jropet syns | M17: 18621.9 | N17: 18621.9 | O17: 2234.63 | R17: Sim | S17: Alta | T17: NOTAS FISCAIS DE COMPRA JANEIRO 2026.pdf - p. 45
A18: JAN26-P046 | B18: 46 | C18: 535509 | D18: 46026 | E18: COMPANHIA INDUSTRIAL DE CIMENTO APODI | F18: 10.260.249/0003-51 | G18: | COMPANHIA INDUSTRIAL DE-CIMENTO APODI | Rofktisea thar | eek | M18: 18839.7 | N18: 18839.7 | O18: 2260.76 | R18: Sim | S18: Media | T18: NOTAS FISCAIS DE COMPRA JANEIRO 2026.pdf - p. 46
A19: JAN26-P053 | B19: 53 | C19: 2198 | D19: 46041 | E19: CAIEIRA CANTA GALO EXTRACAO E COMERCIO DE CALCARIO LTDA | F19: 07.776.339/0002-04 | G19: COMERCIO DE CALCARIO LTDA, | M19: 488 | N19: 215.5 | O19: 25.86 | R19: Sim | S19: Alta | T19: NOTAS FISCAIS DE COMPRA JANEIRO 2026.pdf - p. 53
A20: JAN26-P054 | B20: 54 | C20: 2181 | D20: 46039 | E20: CAIEIRA CANTA GALO EXTRACAO E COMERCIO DE CALCARIO LTDA | F20: 07.776.339/0002-04 | G20: COMERCIO DE CALCARIO LTDA, | DOCUMENTO AUX | IAR DA. | M20: 4392 | N20: 1939.51 | O20: 232.74 | R20: Sim | S20: Alta | T20: NOTAS FISCAIS DE COMPRA JANEIRO 2026.pdf - p. 54
A21: JAN26-P055 | B21: 55 | C21: 17232 | D21: 46035 | E21: PLASTER DISTRIBUIDORA LTDA | F21: 42.534.679/0001-49 | G21: Venda de Producao do Estabelecimento | 126260004521449 | M21: 42165.62 | N21: 42165.62 | O21: 5059.87 | Q21: 1370.38 | R21: Sim | S21: Alta | T21: NOTAS FISCAIS DE COMPRA JANEIRO 2026.pdf - p. 55
A22: JAN26-P059 | B22: 59 | C22: 832 | D22: 46048 | E22: ROMILSON SILVA DE ASSIS | F22: 19.255.075/0001-41 | G22: NIPLE C/ FURO CALIBRADO 1,5 MM / VALVULA NAO RETORNO + VISOR | M22: 350 | R22: Sim | S22: Alta | T22: NOTAS FISCAIS DE COMPRA JANEIRO 2026.pdf - p. 59
A23: JAN26-P077 | B23: 77 | C23: 535011 | D23: 46031 | E23: COMPANHIA INDUSTRIAL DE CIMENTO APODI | F23: 10.260.249/0003-51 | G23: ELECIMENTO. | 09/01/2026 06:22:19 | M23: 15797.5 | N23: 15797.5 | O23: 1895.7 | R23: Sim | S23: Alta | T23: NOTAS FISCAIS DE COMPRA JANEIRO 2026.pdf - p. 77
A24: JAN26-P078 | B24: 78 | C24: 861 | D24: 45972 | E24: INOVE SOLUCOES EM PRODUTOS E EQUIPAMENTOS PARA LABORATORIOS | F24: 60.366.345/0001-95 | M24: 28961 | R24: Sim | S24: Alta | T24: NOTAS FISCAIS DE COMPRA JANEIRO 2026.pdf - p. 78
A25: JAN26-P079 | B25: 79 | C25: 100000086 | D25: 45972 | E25: es, vimos por meio des | F25: 60.366.345/0002-91 | R25: Revisar | S25: Alta | T25: NOTAS FISCAIS DE COMPRA JANEIRO 2026.pdf - p. 79
A26: JAN26-P081 | B26: 81 | C26: 60587 | D26: 46034 | E26: DISTRIBUICAO DE ALIMENTOS VANGUARDA S/A | F26: 31.838.128/0025-20 | G26: SAL MOIDO C/INDUSTRIAL S IODIO 1KG, 1.000 UN x R$ 0,80 | M26: 800 | R26: Sim | S26: Alta | T26: NOTAS FISCAIS DE COMPRA JANEIRO 2026.pdf - p. 81
A27: JAN26-P084 | B27: 84 | C27: 232676 | D27: 46007 | E27: INDUMAK MAQUINAS LTDA | F27: 84.431.352/0001-91 | M27: 1391.53 | N27: 1587.23 | O27: 100.51 | Q27: 75.65 | R27: Sim | S27: Alta | T27: NOTAS FISCAIS DE COMPRA JANEIRO 2026.pdf - p. 84
A28: JAN26-P092 | B28: 92 | C28: 535504 | D28: 46036 | E28: COMPANHIA INDUSTRIAL DE CIMENTO APODI | F28: 10.260.249/0003-51 | G28: coe sasat-o08 mufeulieidade #0 portal wacion NF | | VENDA DE PRODUCAG DO ESTABELECIMENTO_ 14/01/2026 _ 11:40:07 | ipacMCIS ADGA REE S0NS TRIS Tore | ‘SEAL ENGENHARIA INDUSTRIA E COMERCIO LTDA. 34658 038/0002.89 T4u72026 | [SFDERECO. BARD DISTRITO cer | Eveomancscomov emma etnaao ras | M28: 18676.35 | N28: 18676.35 | O28: 2241.16 | R28: Sim | S28: Baixa | T28: NOTAS FISCAIS DE COMPRA JANEIRO 2026.pdf - p. 92
A29: JAN26-P093 | B29: 93 | C29: 535252 | D29: 46034 | E29: COMPANHIA INDUSTRIAL DE CIMENTO APODI | F29: 10.260.249/0003-51 | G29: /RECROEMOS DE CUMPANIOARDUDTRIAL DE CIMENTO APO O5FRODUTOS CONSTANTES DA NOTA FISCAL INDICADA AQLADO NF | * Neosat | ———— DANFE : MT mi | viper, fpeeapommnnmeroomm | seme: | TATTLE | remsucess> 0. TRADA [euvroraceno | M29: 18720.9 | N29: 18720.9 | O29: 2246.51 | R29: Sim | S29: Baixa | T29: NOTAS FISCAIS DE COMPRA JANEIRO 2026.pdf - p. 93
A30: JAN26-P094 | B30: 94 | C30: 535128 | D30: 46032 | E30: COMPANHIA INDUSTRIAL DE CIMENTO APODI | F30: 10.260.249/0003-51 | G30: FPENGADEPRODUCADDOESrAmELEcamrro. ———hwoyne OL tad | VENDA DE PRODUCAQ DO ESTABELECIMENTO. 10/01/2026 _ 01:31:40 | PRECRICRD ESTABAL CR BA SRS TRIS ead | 10260 249003-5 | SKAL ENGENHARIA INDUSTRIA COMERCIO LTDA. goto Toow036 | ‘AV SAO FRANCISCO 4000 VD EXTREMA eors-aso_|1r7026 | M30: 18656.55 | N30: 18656.55 | O30: 2238.79 | R30: Sim | S30: Baixa | T30: NOTAS FISCAIS DE COMPRA JANEIRO 2026.pdf - p. 94
A31: JAN26-P096 | B31: 96 | C31: 534870 | D31: 46029 | E31: COMPANHIA INDUSTRIAL DE CIMENTO APODI | F31: 10.260.249/0003-51 | G31: VENDA DE PRODUCAO DO ESTABELECIMENTO. 07/01/2026 09:19:58 | pesca Sano EE aes RTTIRIS aan | . Issess | eri | SKAL ENGENHARIA INDUSTRIA E COMERC30 LTDA. [23.655.03840002-29 1071 2026 | M31: 18701.1 | N31: 18701.1 | O31: 2244.13 | R31: Sim | S31: Baixa | T31: NOTAS FISCAIS DE COMPRA JANEIRO 2026.pdf - p. 96
A32: JAN26-P097 | B32: 97 | C32: 534761 | D32: 46028 | E32: COMPANHIA INDUSTRIAL DE CIMENTO APODI | F32: 10.260.249/0003-51 | G32: Cimento Portland / produção do estabelecimento - dados fiscais conforme DANFE. | M32: 18785.25 | N32: 18785.25 | O32: 2254.23 | R32: Sim | S32: Baixa | T32: NOTAS FISCAIS DE COMPRA JANEIRO 2026.pdf - p. 97
A33: JAN26-P112 | B33: 112 | C33: 402080 | D33: 46014 | E33: APODI DISTRIBUICAO E LOGISTICA LTDA | F33: 29.190.494/0003-68 | G33: CIMENTO PORTLAND COMP CP II F 32 50KG PBR S STRETCH, 40 sacos x R$45,50 | M33: 1820 | R33: Sim | S33: Alta | T33: NOTAS FISCAIS DE COMPRA JANEIRO 2026.pdf - p. 112
A34: JAN26-P114 | B34: 114 | C34: 20113 | D34: 46008 | E34: DISTRIBUIDORA DE BEBIDAS ATACADAO DA GELA | F34: 37.658.920/0001-01 | G34: IMPERIO LAGER 600ML, 480 un x R$7,50 | M34: 3600 | R34: Sim | S34: Alta | T34: NOTAS FISCAIS DE COMPRA JANEIRO 2026.pdf - p. 114
A35: JAN26-P116 | B35: 116 | C35: 172 | D35: 46031 | E35: EVERARDO SILVA DO NASCIMENTO | F35: 43.140.694/0001-75 | G35: rom Tam [= ria Tis | [Ss [seenemenrvennes [seo fon ome [at Jatone| Se [eta] a |S er] | I 2 ll RR | lee Ironacomenzracxasnoccioriia—_, —_|raas| im [aa >= | ann] aati anal —istomal ae) aol aa ato] | SF [rane FuRD Cowl OF MODLLO | DRTRENGID COM] RETARD Er a | ae i i DD i | fareeane | i 7, | " 2/9 (SD | i Oo i | DDIRVEMENO 9G ( ‘a a H | Rut, 4.009,00 \ i | . HN . | | A fh | sf | ANY | DAPOS ADICIONALS: * | (somata rai 1 | = iy COMPRAS, , i | Pjeaeewm, BE Veena ba Lancans emeel 02% H | pF RO i | YF | ix 2f Presuo - 8698130230 = | Erarge ou UIDRACE j | DATA EHORADA WERESEAC DIANE . {cae -{UG3RLARA IRATE RELI IO | M35: 8238 | R35: Sim | S35: Alta | T35: NOTAS FISCAIS DE COMPRA JANEIRO 2026.pdf - p. 116
A36: JAN26-P119 | B36: 119 | C36: 77338 | D36: 45994 | E36: POLI-GYN EMBALAGENS LTDA | F36: 00.072.331/0001-37 | M36: 29560.9 | N36: 29560.9 | O36: 1182.44 | Q36: 2882.19 | R36: Sim | S36: Alta | T36: NOTAS FISCAIS DE COMPRA JANEIRO 2026.pdf - p. 119
A37: JAN26-P120 | B37: 120 | C37: 535055 | D37: 46031 | E37: COMPANHIA INDUSTRIAL DE CIMENTO APODI | F37: 10.260.249/0003-51 | G37: vena Be FRODU | DA DE PRODUCAD DO ESTABELECIMENTO. 9401/2026 _ 13:42:59 | Peertriaall | pens To 2090051 | ISKAL ENGENHARIA [NDUSTRIA E COMERCIO LTDA. 13,655.03 8/0002-89. 09/01/2026. | Inv SAO | M37: 18805.05 | N37: 18805.05 | O37: 2256.61 | R37: Sim | S37: Alta | T37: NOTAS FISCAIS DE COMPRA JANEIRO 2026.pdf - p. 120
A38: JAN26-P147 | B38: 147 | C38: 3520 | D38: 46028 | E38: BORGES & CAMURCA RESTAURANTES LTDA | F38: 25.140.178/0001-69 | G38: QUENTINHA, 63 UN x R$13,00 | M38: 819 | R38: Sim | S38: Alta | T38: NOTAS FISCAIS DE COMPRA JANEIRO 2026.pdf - p. 147
A39: JAN26-P148 | B39: 148 | C39: 16028 | D39: 46003 | E39: RENOVAR INDUSTRIA E COMERCIO DE EMBALAGENS EIRELI | F39: 04.904.996/0001-10 | G39: fRarinza onortantha FROToCoLO ne aUTORIZACAO DE USO | [VENDA PRODUCAO DO ESTABELECIMENTO. 1246259 156777928 ~ E2/1272028 16:38:25 | | frscaicsoesraacat IRSCRR AD ESTADIIA SUR TRIBUTANIA lor | n2g071647 Jo4.904.996/0001-10 | DESTINATARIOMEMETENTE. | fowrnazdo soca [ere Iaara Da Ewassto | M39: 27236.94 | N39: 27236.94 | O39: 3268.43 | Q39: 2655.6 | R39: Sim | S39: Alta | T39: NOTAS FISCAIS DE COMPRA JANEIRO 2026.pdf - p. 148
A40: JAN26-P150 | B40: 150 | C40: 4834 | D40: 46006 | E40: ELITE PECAS E MAQUINAS LTDA | F40: 32.021.015/0001-22 | G40: ———————— | ~ ~ Recchemos de ELITE PECAS E MAQUINAS LTDA on produtosiservigos comstantcs da NF indica ao lado T | a ‘ wa meade | A SS ASE Fn ' | M40: 880 | N40: 880 | O40: 61.6 | P40: 136.4 | R40: Sim | S40: Alta | T40: NOTAS FISCAIS DE COMPRA JANEIRO 2026.pdf - p. 150
...

Sheet Itens_Servicos
A1: Doc_ID | B1: Pagina | C1: NFS_e | D1: Data | E1: Prestador | F1: CNPJ | G1: Descricao_Servico_OCR | H1: Valor_Servico | I1: BC_ISS | J1: Aliq_ISS | K1: ISS | L1: IRRF_Retido | M1: CSLL_Retida | N1: PIS_Retido | O1: COFINS_Retido | P1: INSS_Retido | Q1: Valor_Liquido | R1: Soma_Contabil | S1: Duplicado_de | T1: Confianca | U1: Fonte
A2: JAN26-P012 | B2: 12 | C2: 863 | D2: 46022 | E2: GESTAO - INOVACAO EMPRESARIAL LTDA | F2: 20.504.019/0001-82 | G2: SERVICO DE ACOMPANHAMENTO DE PROCESSOS ADMINISTRATIVOS, REFERENTE AO MES DE NOVEMBRO DE 2025 | H2: 759 | R2: Sim | T2: Alta | U2: NOTAS FISCAIS DE COMPRA JANEIRO 2026.pdf - p. 12
A3: JAN26-P028 | B3: 28 | D3: 46055 | E3: TERRA NOVA (LOT. Meco 16459, SAO SEBASTIAO. | H3: 7.5 | R3: Sim | T3: Media | U3: NOTAS FISCAIS DE COMPRA JANEIRO 2026.pdf - p. 28
A4: JAN26-P029 | B4: 29 | D4: 46055 | E4: RIGARDO RODRIGUES DE SOUSA 90931442370 | F4: 40.439.061/0001-74 | R4: Revisar | T4: Media | U4: NOTAS FISCAIS DE COMPRA JANEIRO 2026.pdf - p. 29
A5: JAN26-P030 | B5: 30 | D5: 46048 | E5: JESUINO@APOIOCONTABILP.COM | H5: 4198 | K5: 4198 | R5: Sim | T5: Media | U5: NOTAS FISCAIS DE COMPRA JANEIRO 2026.pdf - p. 30
A6: JAN26-P031 | B6: 31 | C6: 5 | D6: 45996 | E6: - REPRESENTANTES COMERCIAIS E AGENTES DO COMERGIO DE MADEIRA, MATERIAL DE CONSTRUCAO E FERRAGENS, | G6: CNAE, 4613. - REPRESENTANTES COMERCIAIS E AGENTES DO COMERGIO DE MADEIRA, MATERIAL DE CONSTRUCAO E FERRAGENS, Service 10,09 - REPRESENTAGAO DE QUALQUER NATUREZA, INCLUSIVE COMERCIAL. Local da prestacie do servigo Pais da prestagdo do servigo TERESINA PL BRASIL | H6: 797.56 | I6: 791.96 | R6: Sim | T6: Media | U6: NOTAS FISCAIS DE COMPRA JANEIRO 2026.pdf - p. 31
A7: JAN26-P035 | B7: 35 | C7: 0 | E7: CONSULTING AND INFORMATION SERVICES LTOA | H7: 9689.93 | I7: 9.68 | K7: 9689.93 | R7: Sim | T7: Media | U7: NOTAS FISCAIS DE COMPRA JANEIRO 2026.pdf - p. 35
A8: JAN26-P039 | B8: 39 | D8: 46016 | E8: AUTO SHOP RASTREAMENTO LTDA | F8: 24.625.077/0001-15 | H8: 1198 | R8: Sim | T8: Media | U8: NOTAS FISCAIS DE COMPRA JANEIRO 2026.pdf - p. 39
A9: JAN26-P040 | B9: 40 | C9: 2 | E9: E-moll | R9: Revisar | T9: Media | U9: NOTAS FISCAIS DE COMPRA JANEIRO 2026.pdf - p. 40
A10: JAN26-P056 | B10: 56 | C10: 27 | D10: 46045 | E10: JAILSON DA CONCEICAO PAIVA | F10: 53.605.493/0001-50 | G10: SERVICO DE CONFECCAO PARA ENSACADEIRA, ROSCA DA ENSACADEIRA, ROSCA DO MISTURADOR, BASE DOS MANCAIS DO ELEVADOR. | H10: 2000 | R10: Sim | T10: Alta | U10: NOTAS FISCAIS DE COMPRA JANEIRO 2026.pdf - p. 56
A11: JAN26-P057 | B11: 57 | C11: 24 | D11: 46048 | E11: EMERSON CANDIDO DE AQUINO 56476779320 | F11: 45.264.826/0001-04 | G11: SERVICO PRESTADO DE ENTREGA DE MERCADORIA | H11: 2500 | R11: Sim | T11: Alta | U11: NOTAS FISCAIS DE COMPRA JANEIRO 2026.pdf - p. 57
A12: JAN26-P058 | B12: 58 | C12: 960441 | D12: 46042 | E12: HOSPITAIS E CLINICAS DO PIAUI S/S LTDA | F12: 00.885.918/0001-65 | G12: 08 WDM 82 | 8s | 109,04 mesa | to F | cs | 3:795,94 Content M. 450 M. Ja Vendar E7266 H. Fatar | spares tet. 02601" Vencinen | 593203 | MP! | [Ries | esinatara | H12: 5901.18 | I12: 5901.18 | J12: 0.05 | K12: 295.05 | R12: Sim | T12: Alta | U12: NOTAS FISCAIS DE COMPRA JANEIRO 2026.pdf - p. 58
A13: JAN26-P060 | B13: 60 | C13: 36 | D13: 46045 | E13: MARCOS JOSE FONTANA HANUS | F13: 57.460.869/0001-36 | G13: REFERENTE A DESPESA NO PERIODO DE 21/01 A 23/01/2026 | H13: 52 | R13: Sim | T13: Alta | U13: NOTAS FISCAIS DE COMPRA JANEIRO 2026.pdf - p. 60
A14: JAN26-P061 | B14: 61 | C14: 330 | D14: 46027 | E14: MINERAR ENGENHARIA E MEIO AMBIENTE LTDA | F14: 37.102.634/0001-65 | G14: PRESTACAO DE SERVICO REFERENTE A CONSULTORIA MENSAL DE ENGENHARIA DE MINAS. | H14: 759 | K14: 759 | R14: Sim | T14: Alta | U14: NOTAS FISCAIS DE COMPRA JANEIRO 2026.pdf - p. 61
A15: JAN26-P062 | B15: 62 | C15: 53 | D15: 46031 | E15: KLESIO KENNEDY REPRESENTACAO DE MATERIAL DE CONSTRUCAO LTDA | F15: 15.439.685/0001-99 | G15: SERVICO DE REPRESENTACAO | H15: 14933 | I15: 14933 | J15: 0.05 | R15: Sim | T15: Alta | U15: NOTAS FISCAIS DE COMPRA JANEIRO 2026.pdf - p. 62
A16: JAN26-P063 | B16: 63 | C16: 244 | D16: 45999 | E16: F. ALVES CAMINHA - ME | F16: 29.100.059/0001-33 | G16: COMISSAO DE VENDAS OUTUBRO E NOVEMBRO DE 2025 | H16: 797.56 | I16: 707.58 | R16: Sim | T16: Alta | U16: NOTAS FISCAIS DE COMPRA JANEIRO 2026.pdf - p. 63
A17: JAN26-P064 | B17: 64 | C17: 221 | D17: 46029 | E17: E & P SOARES DOS SANTOS LTDA - ME | F17: 27.803.620/0001-15 | G17: NF DE REPRESENTACAO COMERCIAL REFERENTE A COMPETENCIA DO MES DE DEZEMBRO DE 2025. | H17: 35238.7 | R17: Sim | T17: Alta | U17: NOTAS FISCAIS DE COMPRA JANEIRO 2026.pdf - p. 64
A18: JAN26-P065 | B18: 65 | C18: 57 | D18: 46029 | E18: F J DE SOUSA REPRESENTACOES | F18: 44.036.268/0001-59 | G18: COMISSAO SOBRE VENDAS - DEZEMBRO/2025. | H18: 14232.77 | R18: Sim | T18: Alta | U18: NOTAS FISCAIS DE COMPRA JANEIRO 2026.pdf - p. 65
A19: JAN26-P066 | B19: 66 | C19: 32 | D19: 46043 | E19: GRACILENE MARIA BEZERRA DOS SANTOS | F19: 54.011.991/0001-37 | G19: SERVICO DE PROMOCAO DE VENDAS. COMPETENCIA DEZEMBRO/2025. | H19: 4782.92 | R19: Sim | T19: Alta | U19: NOTAS FISCAIS DE COMPRA JANEIRO 2026.pdf - p. 66
A20: JAN26-P069 | B20: 69 | C20: 4 | D20: 46048 | E20: JUVENCIO REPRESENTACOES LIMITADA | F20: 07.352.685/0001-84 | G20: COMISSAO SOBRE VENDAS REFERENTE AO MES DE DEZEMBRO DE 2025. | H20: 15662.93 | R20: Revisar | T20: Alta | U20: NOTAS FISCAIS DE COMPRA JANEIRO 2026.pdf - p. 69
A21: JAN26-P070 | B21: 70 | C21: 3 | D21: 46030 | E21: JUVENCIO REPRESENTACOES LIMITADA | F21: 07.352.685/0001-84 | G21: COMISSAO SOBRE VENDAS REFERENTE AO MES DE DEZEMBRO DE 2025. | H21: 15662.93 | R21: Revisar | T21: Alta | U21: NOTAS FISCAIS DE COMPRA JANEIRO 2026.pdf - p. 70
A22: JAN26-P082 | B22: 82 | C22: 767 | D22: 46036 | E22: EDWARD MOURA SOCIEDADE INDIVIDUAL DE ADVOCACIA | F22: 09.244.087/0001-17 | G22: HONORARIOS ADVOCATICIOS | H22: 4075 | K22: 4.07 | R22: Sim | T22: Alta | U22: NOTAS FISCAIS DE COMPRA JANEIRO 2026.pdf - p. 82
A23: JAN26-P083 | B23: 83 | C23: 3331 | D23: 46030 | E23: LCM CONSULTING AND INFORMATION SERVICES LTDA | F23: 04.704.452/0001-05 | G23: REFERENTE A PROPOSTA TOPI0027/2025, PROCEDIMENTO OPERACIONAL CREDITO E COBRANCA. PARCELA 01/03 | H23: 9689.33 | K23: 9.88 | R23: Sim | T23: Alta | U23: NOTAS FISCAIS DE COMPRA JANEIRO 2026.pdf - p. 83
A24: JAN26-P111 | B24: 111 | C24: 536943 | D24: 46022 | E24: CONNECT INFORMACOES E TECNOLOGIA SA | F24: 00.850.820/0001-72 | G24: PROCESSAMENTO E GERENCIAMENTO DE COMUNICACAO DE DADOS PLATAFORMA CONNECTSA | H24: 460 | I24: 460 | J24: 0.02 | K24: 9.2 | R24: Sim | T24: Alta | U24: NOTAS FISCAIS DE COMPRA JANEIRO 2026.pdf - p. 111
A25: JAN26-P113 | B25: 113 | C25: 22 | D25: 46029 | E25: JORGE GUILHERME COSTA FERREIRA | F25: 24.870.571/0001-45 | G25: IMPLANTACAO DE PROJETO GOVERNANCA CORPORATIVA | H25: 500 | R25: Sim | T25: Alta | U25: NOTAS FISCAIS DE COMPRA JANEIRO 2026.pdf - p. 113
A26: JAN26-P131 | B26: 131 | C26: 167 | D26: 46028 | E26: FENIX PRESTADORA DE SERVICOS LTDA | F26: 51.998.593/0001-68 | G26: PRESTACAO DE SERVICO LOCADO NA KALFIX EM TERESINA - PI. SERVICO DE AGENTE DE PORTARIA REFERENTE AO MES DE DEZEMBRO DE 2025. | H26: 8175 | R26: Sim | T26: Alta | U26: NOTAS FISCAIS DE COMPRA JANEIRO 2026.pdf - p. 131
A27: JAN26-P132 | B27: 132 | C27: 166 | D27: 46028 | E27: FENIX PRESTADORA DE SERVICOS LTDA | F27: 51.998.593/0001-68 | G27: PRESTACAO DE SERVICO LOCADO NA CIMEX EM TERESINA - PI. SERVICO DE AGENTE DE PORTARIA REFERENTE AO MES DE DEZEMBRO DE 2025. | H27: 8175 | R27: Sim | T27: Alta | U27: NOTAS FISCAIS DE COMPRA JANEIRO 2026.pdf - p. 132
A28: JAN26-P133 | B28: 133 | C28: 22 | D28: 46034 | E28: EMERSON CANDIDO DE AQUINO 56476779320 | F28: 45.264.826/0001-04 | G28: SERVICO PRESTADO DE ENTREGA DE MERCADORIA | H28: 2000 | R28: Sim | T28: Alta | U28: NOTAS FISCAIS DE COMPRA JANEIRO 2026.pdf - p. 133
A29: JAN26-P135 | B29: 135 | C29: 16004 | D29: 46010 | E29: LENCO CENTRO DE CONTROLE TECNOLOGICO LTDA | F29: 11.257.580/0001-13 | G29: SERVICO PRESTADO DE ENSAIO - ARGAMASSA DE REJUNTAMENTO ACRILICO BRANCO TIPO II LOTE KAL0925 | H29: 750 | I29: 750 | J29: 0.05 | K29: 37.5 | L29: 11.25 | M29: 7.5 | N29: 4.88 | O29: 22.5 | R29: Sim | T29: Alta | U29: NOTAS FISCAIS DE COMPRA JANEIRO 2026.pdf - p. 135
A30: JAN26-P136 | B30: 136 | C30: 3320 | D30: 46029 | E30: LCM CONSULTING AND INFORMATION SERVICES LTDA | F30: 04.704.452/0001-05 | G30: REFERENTE AOS SERVICOS PRESTADOS NO MES DE DEZEMBRO/2025 | H30: 1788.75 | R30: Sim | T30: Alta | U30: NOTAS FISCAIS DE COMPRA JANEIRO 2026.pdf - p. 136
A31: JAN26-P143 | B31: 143 | C31: 3 | D31: 46030 | E31: MICHELA MEDEIROS FRANCO | F31: 64.060.822/0001-40 | G31: SERVICO PRESTADO REF. AO MES DE DEZEMBRO/2025 | H31: 4800 | R31: Sim | T31: Alta | U31: NOTAS FISCAIS DE COMPRA JANEIRO 2026.pdf - p. 143
A32: JAN26-P144 | B32: 144 | C32: 18513 | D32: 46000 | E32: VANGUARD PECAS E SERVICOS AUTOMOTIVOS LTDA | F32: 10.708.117/0001-88 | G32: SERVICO DE AFERICAO DE TACOGRAFO R$58,62; SELAGEM R$68,94; ENSAIO R$142,44. | H32: 270 | I32: 270 | J32: 0.05 | K32: 13.5 | R32: Sim | T32: Alta | U32: NOTAS FISCAIS DE COMPRA JANEIRO 2026.pdf - p. 144
A33: JAN26-P145 | B33: 145 | C33: 9 | D33: 46030 | E33: MARCEL DE MOURA GOMES LTDA | F33: 55.944.213/0001-63 | G33: PRESTACAO DE SERVICOS DE DIVULGACAO DE MARCA KALFIX | H33: 3000 | I33: 3000 | J33: 0.05 | K33: 150 | R33: Sim | T33: Alta | U33: NOTAS FISCAIS DE COMPRA JANEIRO 2026.pdf - p. 145
A34: JAN26-P154 | B34: 154 | C34: 3992/U | D34: 46023 | E34: R F DAS B LEMOS - ME | F34: 08.871.746/0001-90 | G34: Monitoramento de sistemas de segurança. | H34: 751.47 | K34: 37.57 | R34: Sim | T34: Media | U34: NOTAS FISCAIS DE COMPRA JANEIRO 2026.pdf - p. 154
A35: JAN26-P155 | B35: 155 | E35: snessonaonene3 ‘KAL ENGENHARIA NUSTRIAE COMERCIOLTOA | R35: Revisar | T35: Baixa | U35: NOTAS FISCAIS DE COMPRA JANEIRO 2026.pdf - p. 155
A36: JAN26-P157 | B36: 157 | C36: 154628/U | D36: 46023 | E36: NATUS AMBIENTAL LTDA | F36: 12.710.740/0001-09 | G36: Coleta de resíduos. | H36: 1265.53 | K36: 37.96 | R36: Sim | T36: Baixa | U36: NOTAS FISCAIS DE COMPRA JANEIRO 2026.pdf - p. 157
A37: JAN26-P158 | B37: 158 | C37: 154627/U | D37: 46023 | E37: NATUS AMBIENTAL LTDA | F37: 12.710.740/0001-09 | G37: Tratamento e disposição de efluentes/resíduos. | H37: 250.57 | K37: 7.51 | R37: Sim | T37: Media | U37: NOTAS FISCAIS DE COMPRA JANEIRO 2026.pdf - p. 158
A38: JAN26-P159 | B38: 159 | C38: 21 | D38: 46024 | E38: 24.870.571 JORGE GUILHERME COSTA FERREIRA | F38: 24.870.571/0001-45 | G38: Serviço de Gerenciamento Financeiro. | H38: 7000 | R38: Sim | T38: Baixa | U38: NOTAS FISCAIS DE COMPRA JANEIRO 2026.pdf - p. 159
A39: JAN26-P162 | B39: 162 | E39: [:-Xasmceac cons has anspor car seiniano om moet uaa cupwbr ma eka cusp ovo | R39: Revisar | T39: Baixa | U39: NOTAS FISCAIS DE COMPRA JANEIRO 2026.pdf - p. 162
A40: JAN26-P163 | B40: 163 | E40: PORTARIA HOMES DE OEZEMBRO DE 2026, LOCADOS EM TERESINA, | R40: Revisar | T40: Baixa | U40: NOTAS FISCAIS DE COMPRA JANEIRO 2026.pdf - p. 163
...

Sheet Fretes_CTe
A1: Doc_ID | B1: Pagina | C1: CTe | D1: Data | E1: Transportadora | F1: CNPJ_Transportadora | G1: Remetente | H1: CNPJ_Remetente | I1: Destinatario | J1: CNPJ_Destinatario | K1: Valor_Mercadoria | L1: Valor_Frete | M1: BC_ICMS | N1: Aliq_ICMS | O1: ICMS | P1: Soma_Contabil | Q1: Observacoes | R1: Fonte
A2: JAN26-P017 | B2: 17 | C2: 446 | D2: 46050 | E2: F G INTELIGENCIA EM LOGISTICA LTDA | F2: 42.709.787/0003-77 | G2: COMPANHIA INDUSTRIAL DE CIMENTO APODI | H2: 10.260.249/0003-51 | I2: SKAL ENGENHARIA INDUSTRIA E COMERCIO LTDA | J2: 23.655.038/0002-89 | K2: 18686.25 | L2: 11702.5 | M2: 11702.5 | N2: 0.12 | O2: 1404.3 | P2: Sim | R2: NOTAS FISCAIS DE COMPRA JANEIRO 2026.pdf - p. 17
A3: JAN26-P018 | B3: 18 | C3: 445 | D3: 46049 | E3: F G INTELIGENCIA EM LOGISTICA LTDA | F3: 42.709.787/0003-77 | G3: COMPANHIA INDUSTRIAL DE CIMENTO APODI | H3: 10.260.249/0003-51 | I3: SKAL ENGENHARIA INDUSTRIA E COMERCIO LTDA | J3: 23.655.038/0002-89 | K3: 18904.05 | L3: 11838.9 | M3: 11838.9 | N3: 0.12 | O3: 1420.67 | P3: Sim | R3: NOTAS FISCAIS DE COMPRA JANEIRO 2026.pdf - p. 18
A4: JAN26-P019 | B4: 19 | C4: 443 | D4: 46046 | E4: F G INTELIGENCIA EM LOGISTICA LTDA | F4: 42.709.787/0003-77 | G4: COMPANHIA INDUSTRIAL DE CIMENTO APODI | H4: 10.260.249/0003-51 | I4: SKAL ENGENHARIA INDUSTRIA E COMERCIO LTDA | J4: 23.655.038/0002-89 | K4: 18824.85 | L4: 11789.3 | M4: 11789.3 | N4: 0.12 | O4: 1414.72 | P4: Sim | R4: NOTAS FISCAIS DE COMPRA JANEIRO 2026.pdf - p. 19
A5: JAN26-P025 | B5: 25 | E5: TRANS VNC TRANSPORTES EIRELI | I5: SKAL ENGENHARIA INDUSTRIA E COMERCIO LTDA | K5: 9135 | L5: 703 | M5: 410.1 | N5: 0.12 | O5: 49.21 | P5: Revisar | Q5: CT-e TRANS VMC: valor lido visualmente; confirmar chave/total antes da contabilização. | R5: NOTAS FISCAIS DE COMPRA JANEIRO 2026.pdf - p. 25
A6: JAN26-P047 | B6: 47 | C6: 438 | D6: 46045 | E6: F G INTELIGENCIA EM LOGISTICA LTDA | F6: 42.709.787/0003-77 | G6: COMPANHIA INDUSTRIAL DE CIMENTO APODI | H6: 10.260.249/0003-51 | I6: SKAL ENGENHARIA INDUSTRIA E COMERCIO LTDA | J6: 23.655.038/0002-89 | K6: 17790.3 | L6: 11141.4 | M6: 11141.4 | N6: 0.12 | O6: 1336.97 | P6: Sim | R6: NOTAS FISCAIS DE COMPRA JANEIRO 2026.pdf - p. 47
A7: JAN26-P048 | B7: 48 | C7: 433 | D7: 46044 | E7: F G INTELIGENCIA EM LOGISTICA LTDA | F7: 42.709.787/0003-77 | G7: COMPANHIA INDUSTRIAL DE CIMENTO APODI | H7: 10.260.249/0003-51 | I7: SKAL ENGENHARIA INDUSTRIA E COMERCIO LTDA | J7: 23.655.038/0002-89 | K7: 18607.05 | L7: 11652.9 | M7: 11652.9 | N7: 0.12 | O7: 1398.35 | P7: Sim | R7: NOTAS FISCAIS DE COMPRA JANEIRO 2026.pdf - p. 48
A8: JAN26-P049 | B8: 49 | C8: 431 | D8: 46043 | E8: F G INTELIGENCIA EM LOGISTICA LTDA | F8: 42.709.787/0003-77 | G8: COMPANHIA INDUSTRIAL DE CIMENTO APODI | H8: 10.260.249/0003-51 | I8: SKAL ENGENHARIA INDUSTRIA E COMERCIO LTDA | J8: 23.655.038/0002-89 | K8: 18711 | L8: 11718 | M8: 11718 | N8: 0.12 | O8: 1406.16 | P8: Sim | R8: NOTAS FISCAIS DE COMPRA JANEIRO 2026.pdf - p. 49
A9: JAN26-P050 | B9: 50 | C9: 426 | D9: 46042 | E9: F G INTELIGENCIA EM LOGISTICA LTDA | F9: 42.709.787/0003-77 | G9: COMPANHIA INDUSTRIAL DE CIMENTO APODI | H9: 10.260.249/0003-51 | I9: SKAL ENGENHARIA INDUSTRIA E COMERCIO LTDA | J9: 23.655.038/0002-89 | K9: 18814.95 | L9: 11783.1 | M9: 11783.1 | N9: 0.12 | O9: 1413.97 | P9: Sim | R9: NOTAS FISCAIS DE COMPRA JANEIRO 2026.pdf - p. 50
A10: JAN26-P051 | B10: 51 | C10: 421 | D10: 46041 | E10: F G INTELIGENCIA EM LOGISTICA LTDA | F10: 42.709.787/0003-77 | G10: COMPANHIA INDUSTRIAL DE CIMENTO APODI | H10: 10.260.249/0003-51 | I10: SKAL ENGENHARIA INDUSTRIA E COMERCIO LTDA | J10: 23.655.038/0002-89 | K10: 18621.9 | L10: 11662.2 | M10: 11662.2 | N10: 0.12 | O10: 1399.46 | P10: Sim | R10: NOTAS FISCAIS DE COMPRA JANEIRO 2026.pdf - p. 51
A11: JAN26-P052 | B11: 52 | C11: 418 | D11: 46036 | E11: F G INTELIGENCIA EM LOGISTICA LTDA | F11: 42.709.787/0003-77 | G11: COMPANHIA INDUSTRIAL DE CIMENTO APODI | H11: 10.260.249/0003-51 | I11: SKAL ENGENHARIA INDUSTRIA E COMERCIO LTDA | J11: 23.655.038/0002-89 | K11: 18839.7 | L11: 11798.6 | M11: 11798.6 | N11: 0.12 | O11: 1415.83 | P11: Sim | R11: NOTAS FISCAIS DE COMPRA JANEIRO 2026.pdf - p. 52
A12: JAN26-P087 | B12: 87 | C12: 409 | D12: 46032 | E12: F G INTELIGENCIA EM LOGISTICA LTDA | F12: 42.709.787/0003-77 | G12: COMPANHIA INDUSTRIAL DE CIMENTO APODI | H12: 10.260.249/0003-51 | I12: SKAL ENGENHARIA INDUSTRIA E COMERCIO LTDA | J12: 23.655.038/0002-89 | K12: 18656.55 | L12: 11683.9 | M12: 11683.9 | N12: 0.12 | O12: 1402.07 | P12: Sim | R12: NOTAS FISCAIS DE COMPRA JANEIRO 2026.pdf - p. 87
A13: JAN26-P088 | B13: 88 | C13: 408 | D13: 46031 | E13: F G INTELIGENCIA EM LOGISTICA LTDA | F13: 42.709.787/0003-77 | G13: COMPANHIA INDUSTRIAL DE CIMENTO APODI | H13: 10.260.249/0003-51 | I13: SKAL ENGENHARIA INDUSTRIA E COMERCIO LTDA | J13: 23.655.038/0002-89 | K13: 18805.05 | L13: 11776.9 | M13: 11776.9 | N13: 0.12 | O13: 1413.23 | P13: Sim | R13: NOTAS FISCAIS DE COMPRA JANEIRO 2026.pdf - p. 88
A14: JAN26-P089 | B14: 89 | C14: 407 | D14: 46031 | E14: F G INTELIGENCIA EM LOGISTICA LTDA | F14: 42.709.787/0003-77 | G14: COMPANHIA INDUSTRIAL DE CIMENTO APODI | H14: 10.260.249/0003-51 | I14: SKAL ENGENHARIA INDUSTRIA E COMERCIO LTDA | J14: 23.655.038/0002-89 | K14: 15797.5 | L14: 2307.5 | M14: 2307.5 | N14: 0.12 | O14: 276.9 | P14: Sim | R14: NOTAS FISCAIS DE COMPRA JANEIRO 2026.pdf - p. 89
A15: JAN26-P090 | B15: 90 | C15: 405 | D15: 46029 | E15: F G INTELIGENCIA EM LOGISTICA LTDA | F15: 42.709.787/0003-77 | G15: COMPANHIA INDUSTRIAL DE CIMENTO APODI | H15: 10.260.249/0003-51 | I15: SKAL ENGENHARIA INDUSTRIA E COMERCIO LTDA | J15: 23.655.038/0002-89 | K15: 18701.1 | L15: 11711.8 | M15: 11711.8 | N15: 0.12 | O15: 1405.42 | P15: Sim | R15: NOTAS FISCAIS DE COMPRA JANEIRO 2026.pdf - p. 90
A16: JAN26-P091 | B16: 91 | C16: 401 | D16: 46028 | E16: F G INTELIGENCIA EM LOGISTICA LTDA | F16: 42.709.787/0003-77 | G16: COMPANHIA INDUSTRIAL DE CIMENTO APODI | H16: 10.260.249/0003-51 | I16: SKAL ENGENHARIA INDUSTRIA E COMERCIO LTDA | J16: 23.655.038/0002-89 | K16: 18785.25 | L16: 11764.5 | M16: 11764.5 | N16: 0.12 | O16: 1411.74 | P16: Sim | R16: NOTAS FISCAIS DE COMPRA JANEIRO 2026.pdf - p. 91
A17: JAN26-P098 | B17: 98 | C17: 373 | D17: 46004 | E17: F G INTELIGENCIA EM LOGISTICA LTDA | F17: 42.709.787/0003-77 | G17: COMPANHIA INDUSTRIAL DE CIMENTO APODI | H17: 10.260.249/0003-51 | I17: SKAL ENGENHARIA INDUSTRIA E COMERCIO LTDA | J17: 23.655.038/0002-89 | K17: 18834.75 | L17: 11795.5 | M17: 11795.5 | N17: 0.12 | O17: 1415.46 | P17: Sim | R17: NOTAS FISCAIS DE COMPRA JANEIRO 2026.pdf - p. 98
... A29: JAN26-P129 | B29: 129 | C29: 397 | D29: 46021 | E29: F G INTELIGENCIA EM LOGISTICA LTDA | F29: 42.709.787/0003-77 | G29: COMPANHIA INDUSTRIAL DE CIMENTO APODI | H29: 10.260.249/0003-51 | I29: SKAL ENGENHARIA INDUSTRIA E COMERCIO LTDA | J29: 23.655.038/0002-89 | K29: 18681.3 | L29: 11699.4 | M29: 11699.4 | N29: 0.12 | O29: 1403.93 | P29: Sim | R29: NOTAS FISCAIS DE COMPRA JANEIRO 2026.pdf - p. 129

Sheet Energia
A1: Doc_ID | B1: Pagina | C1: NF3e | D1: Data | E1: Vencimento | F1: Fornecedor | G1: CNPJ | H1: Unidade_SKAL | I1: Valor_Documento | J1: BC_ICMS | K1: ICMS | L1: PIS | M1: COFINS | N1: Soma_Contabil | O1: Fonte
A2: JAN26-P001 | B2: 1 | C2: 67912850 | D2: 46053 | E2: 46059 | F2: EQUATORIAL PIAUI DISTRIBUIDORA DE ENERGIA S.A. | G2: 06.840.748/0001-89 | H2: SKAL /0002 | I2: 23789.49 | J2: 21764.76 | K2: 4892.56 | L2: 125.55 | M2: 580.23 | N2: Sim | O2: NOTAS FISCAIS DE COMPRA JANEIRO 2026.pdf - p. 1
A3: JAN26-P003 | B3: 3 | C3: 67620505 | D3: 46048 | E3: 46055 | F3: EQUATORIAL PIAUI DISTRIBUIDORA DE ENERGIA S.A. | G3: 06.840.748/0001-89 | H3: SKAL /0001 | I3: 29.6 | J3: 0 | K3: 0 | L3: 0.2 | M3: 0.92 | N3: Sim | O3: NOTAS FISCAIS DE COMPRA JANEIRO 2026.pdf - p. 3
A4: JAN26-P004 | B4: 4 | C4: 67003437 | D4: 46038 | E4: 46045 | F4: EQUATORIAL PIAUI DISTRIBUIDORA DE ENERGIA S.A. | G4: 06.840.748/0001-89 | H4: SKAL /0001 | I4: 29.78 | J4: 0 | K4: 0 | L4: 0.2 | M4: 0.93 | N4: Sim | O4: NOTAS FISCAIS DE COMPRA JANEIRO 2026.pdf - p. 4
A5: JAN26-P005 | B5: 5 | C5: 67888805 | D5: 46051 | E5: 46058 | F5: EQUATORIAL PIAUI DISTRIBUIDORA DE ENERGIA S.A. | G5: 06.840.748/0002-69 | H5: SKAL /0002 | I5: 843.08 | J5: 773.85 | K5: 174.11 | L5: 4.06 | M5: 18.78 | N5: Sim | O5: NOTAS FISCAIS DE COMPRA JANEIRO 2026.pdf - p. 5

Sheet Tributos_por_Doc
A1: Doc_ID | B1: Pagina | C1: Tipo | D1: Numero | E1: Emitente | F1: Valor_Documento | G1: BC_ICMS | H1: Aliq_ICMS | I1: ICMS | J1: BC_ICMS_ST | K1: ICMS_ST | L1: IPI | M1: PIS | N1: COFINS | O1: BC_ISS | P1: Aliq_ISS | Q1: ISS | R1: IRRF_Retido | S1: CSLL_Retida | T1: PIS_Retido | U1: COFINS_Retido | V1: INSS_Retido | W1: Soma_Contabil | X1: Flag_Fiscal | Y1: Fonte
A2: JAN26-P001 | B2: 1 | C2: Energia/NF3e | D2: 67912850 | E2: EQUATORIAL PIAUI DISTRIBUIDORA DE ENERGIA S.A. | F2: 23789.49 | G2: 21764.76 | H2: 0.225 | I2: 4892.56 | M2: 125.55 | N2: 580.23 | W2: Sim | Y2: NOTAS FISCAIS DE COMPRA JANEIRO 2026.pdf - p. 1
A3: JAN26-P003 | B3: 3 | C3: Energia/NF3e | D3: 67620505 | E3: EQUATORIAL PIAUI DISTRIBUIDORA DE ENERGIA S.A. | F3: 29.6 | G3: 0 | I3: 0 | M3: 0.2 | N3: 0.92 | W3: Sim | Y3: NOTAS FISCAIS DE COMPRA JANEIRO 2026.pdf - p. 3
A4: JAN26-P004 | B4: 4 | C4: Energia/NF3e | D4: 67003437 | E4: EQUATORIAL PIAUI DISTRIBUIDORA DE ENERGIA S.A. | F4: 29.78 | G4: 0 | I4: 0 | M4: 0.2 | N4: 0.93 | W4: Sim | Y4: NOTAS FISCAIS DE COMPRA JANEIRO 2026.pdf - p. 4
A5: JAN26-P005 | B5: 5 | C5: Energia/NF3e | D5: 67888805 | E5: EQUATORIAL PIAUI DISTRIBUIDORA DE ENERGIA S.A. | F5: 843.08 | G5: 773.85 | H5: 0.225 | I5: 174.11 | M5: 4.06 | N5: 18.78 | W5: Sim | Y5: NOTAS FISCAIS DE COMPRA JANEIRO 2026.pdf - p. 5
A6: JAN26-P012 | B6: 12 | C6: NFS-e | D6: 863 | E6: GESTAO - INOVACAO EMPRESARIAL LTDA | F6: 759 | W6: Sim | Y6: NOTAS FISCAIS DE COMPRA JANEIRO 2026.pdf - p. 12
A7: JAN26-P013 | B7: 13 | C7: NFS-e | D7: 863 | E7: GESTAO - INOVACAO EMPRESARIAL LTDA | F7: 759 | W7: Não | Y7: NOTAS FISCAIS DE COMPRA JANEIRO 2026.pdf - p. 13
A8: JAN26-P014 | B8: 14 | C8: NFCom | D8: 303 | E8: TELEVISAO PIONEIRA LTDA | F8: 10000 | G8: 0 | I8: 0 | M8: 65 | N8: 300 | W8: Sim | Y8: NOTAS FISCAIS DE COMPRA JANEIRO 2026.pdf - p. 14
A9: JAN26-P017 | B9: 17 | C9: CT-e | D9: 446 | E9: F G INTELIGENCIA EM LOGISTICA LTDA | F9: 11702.5 | G9: 11702.5 | H9: 0.12 | I9: 1404.3 | W9: Sim | Y9: NOTAS FISCAIS DE COMPRA JANEIRO 2026.pdf - p. 17
A10: JAN26-P018 | B10: 18 | C10: CT-e | D10: 445 | E10: F G INTELIGENCIA EM LOGISTICA LTDA | F10: 11838.9 | G10: 11838.9 | H10: 0.12 | I10: 1420.67 | W10: Sim | Y10: NOTAS FISCAIS DE COMPRA JANEIRO 2026.pdf - p. 18
A11: JAN26-P019 | B11: 19 | C11: CT-e | D11: 443 | E11: F G INTELIGENCIA EM LOGISTICA LTDA | F11: 11789.3 | G11: 11789.3 | H11: 0.12 | I11: 1414.72 | W11: Sim | Y11: NOTAS FISCAIS DE COMPRA JANEIRO 2026.pdf - p. 19
A12: JAN26-P022 | B12: 22 | C12: NF-e | D12: 537098 | E12: COMPANHIA INDUSTRIAL DE CIMENTO APODI | F12: 18686.25 | G12: 18686.25 | H12: 0.12 | I12: 2242.35 | W12: Sim | Y12: NOTAS FISCAIS DE COMPRA JANEIRO 2026.pdf - p. 22
A13: JAN26-P023 | B13: 23 | C13: NF-e | D13: 536966 | E13: COMPANHIA INDUSTRIAL DE CIMENTO APODI | F13: 18904.05 | G13: 18904.05 | H13: 0.12 | I13: 2268.49 | W13: Sim | Y13: NOTAS FISCAIS DE COMPRA JANEIRO 2026.pdf - p. 23
A14: JAN26-P024 | B14: 24 | C14: NF-e | D14: 536748 | E14: COMPANHIA INDUSTRIAL DE CIMENTO APODI | F14: 18824.85 | G14: 18824.85 | H14: 0.12 | I14: 2258.98 | W14: Sim | Y14: NOTAS FISCAIS DE COMPRA JANEIRO 2026.pdf - p. 24
A15: JAN26-P025 | B15: 25 | C15: CT-e | E15: TRANS VNC TRANSPORTES EIRELI | F15: 703 | G15: 410.1 | H15: 0.12 | I15: 49.21 | W15: Revisar | Y15: NOTAS FISCAIS DE COMPRA JANEIRO 2026.pdf - p. 25
A16: JAN26-P028 | B16: 28 | C16: NFS-e | E16: TERRA NOVA (LOT. Meco 16459, SAO SEBASTIAO. | F16: 7.5 | M16: 0 | N16: 0 | W16: Sim | Y16: NOTAS FISCAIS DE COMPRA JANEIRO 2026.pdf - p. 28
A17: JAN26-P030 | B17: 30 | C17: NFS-e | E17: JESUINO@APOIOCONTABILP.COM | F17: 4198 | N17: 0 | Q17: 4198 | W17: Sim | X17: ISS OCR suspeito | Y17: NOTAS FISCAIS DE COMPRA JANEIRO 2026.pdf - p. 30
A18: JAN26-P031 | B18: 31 | C18: NFS-e | D18: 5 | E18: - REPRESENTANTES COMERCIAIS E AGENTES DO COMERGIO DE MADEIRA, MATERIAL DE CONSTRUCAO E FERRAGENS, | F18: 797.56 | O18: 791.96 | W18: Sim | Y18: NOTAS FISCAIS DE COMPRA JANEIRO 2026.pdf - p. 31
A19: JAN26-P035 | B19: 35 | C19: NFS-e | D19: 0 | E19: CONSULTING AND INFORMATION SERVICES LTOA | F19: 9689.93 | M19: 0 | O19: 9.68 | Q19: 9689.93 | W19: Sim | X19: ISS OCR suspeito | Y19: NOTAS FISCAIS DE COMPRA JANEIRO 2026.pdf - p. 35
A20: JAN26-P039 | B20: 39 | C20: NFS-e | E20: AUTO SHOP RASTREAMENTO LTDA | F20: 1198 | W20: Sim | Y20: NOTAS FISCAIS DE COMPRA JANEIRO 2026.pdf - p. 39
A21: JAN26-P041 | B21: 41 | C21: NF-e | D21: 536564 | E21: COMPANHIA INDUSTRIAL DE CIMENTO APODI | F21: 17790.3 | G21: 17790.3 | H21: 0.12 | I21: 2134.84 | W21: Sim | Y21: NOTAS FISCAIS DE COMPRA JANEIRO 2026.pdf - p. 41
A22: JAN26-P042 | B22: 42 | C22: NF-e | D22: 536357 | E22: COMPANHIA INDUSTRIAL DE CIMENTO APODI | F22: 18607.05 | G22: 18607.05 | H22: 0.12 | I22: 2232.85 | W22: Sim | Y22: NOTAS FISCAIS DE COMPRA JANEIRO 2026.pdf - p. 42
A23: JAN26-P043 | B23: 43 | C23: NF-e | D23: 536302 | E23: COMPANHIA INDUSTRIAL DE CIMENTO APODI | F23: 18711 | G23: 18711 | H23: 0.12 | I23: 2245.32 | W23: Sim | Y23: NOTAS FISCAIS DE COMPRA JANEIRO 2026.pdf - p. 43
A24: JAN26-P044 | B24: 44 | C24: NF-e | D24: 536108 | E24: COMPANHIA INDUSTRIAL DE CIMENTO APODI | F24: 18814.95 | G24: 18814.95 | H24: 0.12 | I24: 2257.79 | W24: Sim | Y24: NOTAS FISCAIS DE COMPRA JANEIRO 2026.pdf - p. 44
A25: JAN26-P045 | B25: 45 | C25: NF-e | D25: 535954 | E25: COMPANHIA INDUSTRIAL DE CIMENTO APODI | F25: 18621.9 | G25: 18621.9 | H25: 0.12 | I25: 2234.63 | W25: Sim | Y25: NOTAS FISCAIS DE COMPRA JANEIRO 2026.pdf - p. 45
A26: JAN26-P046 | B26: 46 | C26: NF-e | D26: 535509 | E26: COMPANHIA INDUSTRIAL DE CIMENTO APODI | F26: 18839.7 | G26: 18839.7 | H26: 0.12 | I26: 2260.76 | W26: Sim | Y26: NOTAS FISCAIS DE COMPRA JANEIRO 2026.pdf - p. 46
A27: JAN26-P047 | B27: 47 | C27: CT-e | D27: 438 | E27: F G INTELIGENCIA EM LOGISTICA LTDA | F27: 11141.4 | G27: 11141.4 | H27: 0.12 | I27: 1336.97 | W27: Sim | Y27: NOTAS FISCAIS DE COMPRA JANEIRO 2026.pdf - p. 47
A28: JAN26-P048 | B28: 48 | C28: CT-e | D28: 433 | E28: F G INTELIGENCIA EM LOGISTICA LTDA | F28: 11652.9 | G28: 11652.9 | H28: 0.12 | I28: 1398.35 | W28: Sim | Y28: NOTAS FISCAIS DE COMPRA JANEIRO 2026.pdf - p. 48
A29: JAN26-P049 | B29: 49 | C29: CT-e | D29: 431 | E29: F G INTELIGENCIA EM LOGISTICA LTDA | F29: 11718 | G29: 11718 | H29: 0.12 | I29: 1406.16 | W29: Sim | Y29: NOTAS FISCAIS DE COMPRA JANEIRO 2026.pdf - p. 49
A30: JAN26-P050 | B30: 50 | C30: CT-e | D30: 426 | E30: F G INTELIGENCIA EM LOGISTICA LTDA | F30: 11783.1 | G30: 11783.1 | H30: 0.12 | I30: 1413.97 | W30: Sim | Y30: NOTAS FISCAIS DE COMPRA JANEIRO 2026.pdf - p. 50
A31: JAN26-P051 | B31: 51 | C31: CT-e | D31: 421 | E31: F G INTELIGENCIA EM LOGISTICA LTDA | F31: 11662.2 | G31: 11662.2 | H31: 0.12 | I31: 1399.46 | W31: Sim | Y31: NOTAS FISCAIS DE COMPRA JANEIRO 2026.pdf - p. 51
A32: JAN26-P052 | B32: 52 | C32: CT-e | D32: 418 | E32: F G INTELIGENCIA EM LOGISTICA LTDA | F32: 11798.6 | G32: 11798.6 | H32: 0.12 | I32: 1415.83 | W32: Sim | Y32: NOTAS FISCAIS DE COMPRA JANEIRO 2026.pdf - p. 52
... A34: JAN26-P054 | B34: 54 | C34: NF-e | D34: 2181 | E34: CAIEIRA CANTA GALO EXTRACAO E COMERCIO DE CALCARIO LTDA | F34: 4392 | G34: 1939.51 | H34: 0.12 | I34: 232.74 | W34: Sim | Y34: NOTAS FISCAIS DE COMPRA JANEIRO 2026.pdf - p. 54
A35: JAN26-P055 | B35: 55 | C35: NF-e | D35: 17232 | E35: PLASTER DISTRIBUIDORA LTDA | F35: 43536 | G35: 42165.62 | I35: 5059.87 | L35: 1370.38 | M35: 612.24 | N35: 2820.04 | W35: Sim | Y35: NOTAS FISCAIS DE COMPRA JANEIRO 2026.pdf - p. 55
A36: JAN26-P056 | B36: 56 | C36: NFS-e | D36: 27 | E36: JAILSON DA CONCEICAO PAIVA | F36: 2000 | M36: 0 | N36: 0 | W36: Sim | Y36: NOTAS FISCAIS DE COMPRA JANEIRO 2026.pdf - p. 56
A37: JAN26-P057 | B37: 57 | C37: NFS-e | D37: 24 | E37: EMERSON CANDIDO DE AQUINO 56476779320 | F37: 2500 | W37: Sim | Y37: NOTAS FISCAIS DE COMPRA JANEIRO 2026.pdf - p. 57
A38: JAN26-P058 | B38: 58 | C38: NFS-e | D38: 960441 | E38: HOSPITAIS E CLINICAS DO PIAUI S/S LTDA | F38: 5901.18 | O38: 5901.18 | P38: 0.05 | Q38: 295.05 | W38: Sim | Y38: NOTAS FISCAIS DE COMPRA JANEIRO 2026.pdf - p. 58
A39: JAN26-P059 | B39: 59 | C39: NF-e | D39: 832 | E39: ROMILSON SILVA DE ASSIS | F39: 350 | W39: Sim | Y39: NOTAS FISCAIS DE COMPRA JANEIRO 2026.pdf - p. 59
A40: JAN26-P060 | B40: 60 | C40: NFS-e | D40: 36 | E40: MARCOS JOSE FONTANA HANUS | F40: 52 | M40: 62 | N40: 62 | W40: Sim | Y40: NOTAS FISCAIS DE COMPRA JANEIRO 2026.pdf - p. 60
A41: JAN26-P061 | B41: 61 | C41: NFS-e | D41: 330 | E41: MINERAR ENGENHARIA E MEIO AMBIENTE LTDA | F41: 759 | Q41: 759 | W41: Sim | X41: ISS OCR suspeito | Y41: NOTAS FISCAIS DE COMPRA JANEIRO 2026.pdf - p. 61
...
